<?xml version="1.0"?>
<!-- =================================================================================== -->
<!-- |    This document was autogenerated by xacro from ur5_robot.urdf.xacro           | -->
<!-- |    EDITING THIS FILE BY HAND IS NOT RECOMMENDED                                 | -->
<!-- =================================================================================== -->
<robot name="ur5" xmlns:xacro="http://wiki.ros.org/xacro">
    <!-- This is the sign-language robot's description file, with two ur5 arms and two
    inspire-hands. -->
    <!-- Add mimic joint plugin for the gripper -->
    <!--gazebo>
    <!- - left gripper's mimic joints- ->
    <plugin name="MimicJointPlugin_left_rh_r2"
    filename="libroboticsgroup_gazebo_mimic_joint_plugin.so">
      <joint>left_rh_p12_rn</joint>
      <mimicJoint>left_rh_r2</mimicJoint>
      <multiplier>0.9090909</multiplier>
    </plugin>
    <plugin name="MimicJointPlugin_left_rh_l1"
    filename="libroboticsgroup_gazebo_mimic_joint_plugin.so">
      <joint>left_rh_p12_rn</joint>
      <mimicJoint>left_rh_l1</mimicJoint>
      <multiplier>1.0</multiplier>
    </plugin>
    <plugin name="MimicJointPlugin_left_rh_l2"
    filename="libroboticsgroup_gazebo_mimic_joint_plugin.so">
      <joint>left_rh_p12_rn</joint>
      <mimicJoint>left_rh_l2</mimicJoint>
      <multiplier>0.9090909</multiplier>
    </plugin>

    <!- - right gripper's mimic joints- ->
    <plugin name="MimicJointPlugin_right_rh_r2"
    filename="libroboticsgroup_gazebo_mimic_joint_plugin.so">
      <joint>right_rh_p12_rn</joint>
      <mimicJoint>right_rh_r2</mimicJoint>
      <multiplier>0.9090909</multiplier>
    </plugin>
    <plugin name="MimicJointPlugin_right_rh_l1"
    filename="libroboticsgroup_gazebo_mimic_joint_plugin.so">
      <joint>right_rh_p12_rn</joint>
      <mimicJoint>right_rh_l1</mimicJoint>
      <multiplier>1.0</multiplier>
    </plugin>
    <plugin name="MimicJointPlugin_right_rh_l2"
    filename="libroboticsgroup_gazebo_mimic_joint_plugin.so">
      <joint>right_rh_p12_rn</joint>
      <mimicJoint>right_rh_l2</mimicJoint>
      <multiplier>0.9090909</multiplier>
    </plugin>
  </gazebo-->
    <!--
    <plugin name="gazebo_ros_power_monitor_controller" filename="libgazebo_ros_power_monitor.so">
      <alwaysOn>true</alwaysOn>
      <updateRate>1.0</updateRate>
      <timeout>5</timeout>
      <powerStateTopic>power_state</powerStateTopic>
      <powerStateRate>10.0</powerStateRate>
      <fullChargeCapacity>87.78</fullChargeCapacity>
      <dischargeRate>-474</dischargeRate>
      <chargeRate>525</chargeRate>
      <dischargeVoltage>15.52</dischargeVoltage>
      <chargeVoltage>16.41</chargeVoltage>
    </plugin>
-->
    <gazebo>
        <plugin name="gazebo_ros_control" filename="libgazebo_ros_control.so">
            <robotNamespace>/</robotNamespace>
        </plugin>
    </gazebo>
    <!-- measured from model -->
    <!--property
    name="shoulder_height" value="0.089159" /-->
    <!--property
    name="shoulder_offset" value="0.13585" /-->
    <!-- shoulder_offset - elbow_offset + wrist_1_length = 0.10915 -->
    <!--property
    name="upper_arm_length" value="0.42500" /-->
    <!--property
    name="elbow_offset" value="0.1197" /-->
    <!-- CAD measured -->
    <!--property
    name="forearm_length" value="0.39225" /-->
    <!--property
    name="wrist_1_length" value="0.093" /-->
    <!-- CAD measured -->
    <!--property
    name="wrist_2_length" value="0.09465" /-->
    <!-- In CAD this distance is 0.930, but in the spec it is 0.09465 -->
    <!--property
    name="wrist_3_length" value="0.0823" /-->
    <!-- manually measured -->
    <link name="left_base_link">
        <visual>
            <geometry>
                <mesh filename="package://ur_description/meshes/ur5/visual/base.dae" />
            </geometry>
            <material name="LightGrey">
                <color rgba="0.7 0.7 0.7 1.0" />
            </material>
        </visual>
        <collision>
            <geometry>
                <mesh filename="package://ur_description/meshes/ur5/collision/base.stl" />
            </geometry>
        </collision>
        <inertial>
            <mass value="4.0" />
            <origin rpy="0 0 0" xyz="0.0 0.0 0.0" />
            <inertia ixx="0.00443333156" ixy="0.0" ixz="0.0" iyy="0.00443333156" iyz="0.0"
                izz="0.0072" />
        </inertial>
    </link>
    <joint name="left_shoulder_pan_joint" type="revolute">
        <parent link="left_base_link" />
        <child link="left_shoulder_link" />
        <origin rpy="0.0 0.0 0.0" xyz="0.0 0.0 0.089159" />
        <axis xyz="0 0 1" />
        <limit effort="150.0" lower="-6.28318530718" upper="6.28318530718" velocity="3.15" />
        <dynamics damping="0.0" friction="0.0" />
    </joint>
    <link name="left_shoulder_link">
        <visual>
            <geometry>
                <mesh filename="package://ur_description/meshes/ur5/visual/shoulder.dae" />
            </geometry>
            <material name="LightGrey">
                <color rgba="0.7 0.7 0.7 1.0" />
            </material>
        </visual>
        <collision>
            <geometry>
                <mesh filename="package://ur_description/meshes/ur5/collision/shoulder.stl" />
            </geometry>
        </collision>
        <inertial>
            <mass value="3.7" />
            <!-- <origin rpy="0 0 0" xyz="0.0 0.0 0.0" /> -->
            <origin rpy="0.0 0.0 0.0" xyz="0.0 0.00193 -0.02561" />
            <inertia ixx="0.010267495893" ixy="0.0" ixz="0.0" iyy="0.010267495893" iyz="0.0"
                izz="0.00666" />
        </inertial>
    </link>
    <joint name="left_shoulder_lift_joint" type="revolute">
        <parent link="left_shoulder_link" />
        <child link="left_upper_arm_link" />
        <!-- <origin rpy="0.0 0.78539816339 0.0" xyz="0.0 0.13585 0.0" /> -->
        <origin rpy="0.0 1.570796325 0.0" xyz="0.0 0.13585 0.0" />
        <axis xyz="0 1 0" />
        <limit effort="150.0" lower="-6.2831853" upper="6.2831853" velocity="3.15" />
        <dynamics damping="0.0" friction="0.0" />
    </joint>
    <link name="left_upper_arm_link">
        <visual>
            <geometry>
                <mesh filename="package://ur_description/meshes/ur5/visual/upperarm.dae" />
            </geometry>
            <material name="LightGrey">
                <color rgba="0.7 0.7 0.7 1.0" />
            </material>
        </visual>
        <collision>
            <geometry>
                <mesh filename="package://ur_description/meshes/ur5/collision/upperarm.stl" />
            </geometry>
        </collision>
        <inertial>
            <mass value="8.393" />
            <!-- <origin rpy="0 0 0" xyz="0.0 0.0 0.28" /> -->
            <origin rpy="0.0 0.0 0.0" xyz="0.0 -0.024201 0.2125" />
            <inertia ixx="0.22689067591" ixy="0.0" ixz="0.0" iyy="0.22689067591" iyz="0.0"
                izz="0.0151074" />
        </inertial>
    </link>
    <joint name="left_elbow_joint" type="revolute">
        <parent link="left_upper_arm_link" />
        <child link="left_forearm_link" />
        <!-- <origin rpy="0.0 1.57079632679 0.0" xyz="0.0 -0.1197 0.425" /> -->
        <origin rpy="0.0 0.0 0.0" xyz="0.0 -0.1197 0.425" />
        <axis xyz="0 1 0" />
        <limit effort="150.0" lower="-6.2831853" upper="6.2831853" velocity="3.15" />
        <dynamics damping="0.0" friction="0.0" />
    </joint>
    <link name="left_forearm_link">
        <visual>
            <geometry>
                <mesh filename="package://ur_description/meshes/ur5/visual/forearm.dae" />
            </geometry>
            <material name="LightGrey">
                <color rgba="0.7 0.7 0.7 1.0" />
            </material>
        </visual>
        <collision>
            <geometry>
                <mesh filename="package://ur_description/meshes/ur5/collision/forearm.stl" />
            </geometry>
        </collision>
        <inertial>
            <mass value="2.275" />
            <!-- <origin rpy="0 0 0" xyz="0.0 0.0 0.25" /> -->
            <origin rpy="0.0 0.0 0.0" xyz="0.0 0.0265 0.11993" />
            <inertia ixx="0.049443313556" ixy="0.0" ixz="0.0" iyy="0.049443313556" iyz="0.0"
                izz="0.004095" />
        </inertial>
    </link>
    <joint name="left_wrist_1_joint" type="revolute">
        <parent link="left_forearm_link" />
        <child link="left_wrist_1_link" />
        <origin rpy="0.0 1.57079632679 0.0" xyz="0.0 0.0 0.39225" />
        <axis xyz="0 1 0" />
        <limit effort="28.0" lower="-6.2831853" upper="6.2831853" velocity="3.14159265" />
        <dynamics damping="0.0" friction="0.0" />
    </joint>
    <link name="left_wrist_1_link">
        <visual>
            <geometry>
                <mesh filename="package://ur_description/meshes/ur5/visual/wrist1.dae" />
            </geometry>
            <material name="LightGrey">
                <color rgba="0.7 0.7 0.7 1.0" />
            </material>
        </visual>
        <collision>
            <geometry>
                <mesh filename="package://ur_description/meshes/ur5/collision/wrist1.stl" />
            </geometry>
        </collision>
        <inertial>
            <mass value="1.219" />
            <!-- <origin rpy="0 0 0" xyz="0.0 0.0 0.0" /> -->
            <origin rpy="0.0 0.0 0.0" xyz="0.0 0.110949 0.01634" />
            <inertia ixx="0.111172755531" ixy="0.0" ixz="0.0" iyy="0.111172755531" iyz="0.0"
                izz="0.21942" />
        </inertial>
    </link>
    <joint name="left_wrist_2_joint" type="revolute">
        <parent link="left_wrist_1_link" />
        <child link="left_wrist_2_link" />
        <!-- <origin rpy="0.0 0.0 1.57079632679" xyz="0.0 0.093 0.0" /> -->
        <origin rpy="0.0 0.0 0.0" xyz="0.0 0.093 0.0" />
        <axis xyz="0 0 1" />
        <limit effort="28.0" lower="-6.2831853" upper="6.2831853" velocity="3.2" />
        <dynamics damping="0.0" friction="0.0" />
    </joint>
    <link name="left_wrist_2_link">
        <visual>
            <geometry>
                <mesh filename="package://ur_description/meshes/ur5/visual/wrist2.dae" />
            </geometry>
            <material name="LightGrey">
                <color rgba="0.7 0.7 0.7 1.0" />
            </material>
        </visual>
        <collision>
            <geometry>
                <mesh filename="package://ur_description/meshes/ur5/collision/wrist2.stl" />
            </geometry>
        </collision>
        <inertial>
            <mass value="1.219" />
            <!-- <origin rpy="0 0 0" xyz="0.0 0.0 0.0" /> -->
            <origin rpy="0.0 0.0 0.0" xyz="0.0 0.0018 0.11099" />
            <inertia ixx="0.111172755531" ixy="0.0" ixz="0.0" iyy="0.111172755531" iyz="0.0"
                izz="0.21942" />
        </inertial>
    </link>
    <joint name="left_wrist_3_joint" type="revolute">
        <parent link="left_wrist_2_link" />
        <child link="left_wrist_3_link" />
        <origin rpy="0.0 0.0 0.0" xyz="0.0 0.0 0.09465" />
        <axis xyz="0 1 0" />
        <limit effort="28.0" lower="-6.2831853" upper="6.2831853" velocity="3.2" />
        <dynamics damping="0.0" friction="0.0" />
    </joint>
    <link name="left_wrist_3_link">
        <visual>
            <geometry>
                <mesh filename="package://ur_description/meshes/ur5/visual/wrist3.dae" />
            </geometry>
            <material name="LightGrey">
                <color rgba="0.7 0.7 0.7 1.0" />
            </material>
        </visual>
        <collision>
            <geometry>
                <mesh filename="package://ur_description/meshes/ur5/collision/wrist3.stl" />
            </geometry>
        </collision>
        <inertial>
            <mass value="0.1879" />
            <!-- <origin rpy="0 0 0" xyz="0.0 0.0 0.0" /> -->
            <origin rpy="0.0 0.0 0.0" xyz="0.0 0.001159 0.0" />
            <inertia ixx="0.0171364731454" ixy="0.0" ixz="0.0" iyy="0.0171364731454" iyz="0.0"
                izz="0.033822" />
        </inertial>
    </link>
    <joint name="left_ee_fixed_joint" type="fixed">
        <parent link="left_wrist_3_link" />
        <child link="left_ee_link" />
        <origin rpy="0.0 0.0 1.57079632679" xyz="0.0 0.0823 0.0" />
    </joint>
    <link name="left_ee_link">
        <collision>
            <geometry>
                <box size="0.01 0.01 0.01" />
            </geometry>
            <origin rpy="0 0 0" xyz="-0.01 0 0" />
        </collision>
        <inertial>
            <mass value="0.1" />
            <origin xyz="0 0 0" rpy="0 0 0" />
            <inertia ixx="0.03" iyy="0.03" izz="0.03" ixy="0.0" ixz="0.0" iyz="0.0" />
        </inertial>
    </link>
    <!-- Frame coincident with all-zeros TCP on UR controller -->
    <link name="world" />
    <joint name="left_arm_temp_joint" type="fixed">
        <parent link="world" />
        <child link="left_arm_temp" />
        <origin rpy="-0.78539816339 0.0 0.0" xyz="-0.06 0.235 0.415" />
    </joint>
    <link name="left_arm_temp" />
    <joint name="left_world_joint" type="fixed">
        <parent link="left_arm_temp" />
        <child link="left_base_link" />
        <origin rpy="0.0 0.0 -0.785" xyz="-0.001 -0.004 0.0" />
    </joint>
    <!-- measured from model -->
    <!--property
    name="shoulder_height" value="0.089159" /-->
    <!--property
    name="shoulder_offset" value="0.13585" /-->
    <!-- shoulder_offset - elbow_offset + wrist_1_length = 0.10915 -->
    <!--property
    name="upper_arm_length" value="0.42500" /-->
    <!--property
    name="elbow_offset" value="0.1197" /-->
    <!-- CAD measured -->
    <!--property
    name="forearm_length" value="0.39225" /-->
    <!--property
    name="wrist_1_length" value="0.093" /-->
    <!-- CAD measured -->
    <!--property
    name="wrist_2_length" value="0.09465" /-->
    <!-- In CAD this distance is 0.930, but in the spec it is 0.09465 -->
    <!--property
    name="wrist_3_length" value="0.0823" /-->
    <!-- manually measured -->
    <link name="right_base_link">
        <visual>
            <geometry>
                <mesh filename="package://ur_description/meshes/ur5/visual/base.dae" />
            </geometry>
            <material name="LightGrey">
                <color rgba="0.7 0.7 0.7 1.0" />
            </material>
        </visual>
        <collision>
            <geometry>
                <mesh filename="package://ur_description/meshes/ur5/collision/base.stl" />
            </geometry>
        </collision>
        <inertial>
            <mass value="4.0" />
            <origin rpy="0 0 0" xyz="0.0 0.0 0.0" />
            <inertia ixx="0.00443333156" ixy="0.0" ixz="0.0" iyy="0.00443333156" iyz="0.0"
                izz="0.0072" />
        </inertial>
    </link>
    <joint name="right_shoulder_pan_joint" type="revolute">
        <parent link="right_base_link" />
        <child link="right_shoulder_link" />
        <origin rpy="0.0 0.0 0.0" xyz="0.0 0.0 0.089159" />
        <axis xyz="0 0 1" />
        <limit effort="150.0" lower="-6.28318530718" upper="6.28318530718" velocity="3.15" />
        <dynamics damping="0.0" friction="0.0" />
    </joint>
    <link name="right_shoulder_link">
        <visual>
            <geometry>
                <mesh filename="package://ur_description/meshes/ur5/visual/shoulder.dae" />
            </geometry>
            <material name="LightGrey">
                <color rgba="0.7 0.7 0.7 1.0" />
            </material>
        </visual>
        <collision>
            <geometry>
                <mesh filename="package://ur_description/meshes/ur5/collision/shoulder.stl" />
            </geometry>
        </collision>
        <inertial>
            <mass value="3.7" />
            <!-- <origin rpy="0 0 0" xyz="0.0 0.0 0.0" /> -->
            <origin rpy="0.0 0.0 0.0" xyz="0.0 0.00193 -0.02561" />
            <inertia ixx="0.010267495893" ixy="0.0" ixz="0.0" iyy="0.010267495893" iyz="0.0"
                izz="0.00666" />
        </inertial>
    </link>
    <joint name="right_shoulder_lift_joint" type="revolute">
        <parent link="right_shoulder_link" />
        <child link="right_upper_arm_link" />
        <!-- <origin rpy="0.0  -0.78539816339 0.0" xyz="0.0 0.13585 0.0" /> -->
        <origin rpy="0.0 1.570796325 0.0" xyz="0.0 0.13585 0.0" />
        <axis xyz="0 1 0" />
        <limit effort="150.0" lower="-6.2831853" upper="6.2831853" velocity="3.15" />
        <dynamics damping="0.0" friction="0.0" />
    </joint>
    <link name="right_upper_arm_link">
        <visual>
            <geometry>
                <mesh filename="package://ur_description/meshes/ur5/visual/upperarm.dae" />
            </geometry>
            <material name="LightGrey">
                <color rgba="0.7 0.7 0.7 1.0" />
            </material>
        </visual>
        <collision>
            <geometry>
                <mesh filename="package://ur_description/meshes/ur5/collision/upperarm.stl" />
            </geometry>
        </collision>
        <inertial>
            <mass value="8.393" />
            <!-- <origin rpy="0 0 0" xyz="0.0 0.0 0.28" /> -->
            <origin rpy="0.0 0.0 0.0" xyz="0.0 -0.024201 0.2125" />
            <inertia ixx="0.22689067591" ixy="0.0" ixz="0.0" iyy="0.22689067591" iyz="0.0"
                izz="0.0151074" />
        </inertial>
    </link>
    <joint name="right_elbow_joint" type="revolute">
        <parent link="right_upper_arm_link" />
        <child link="right_forearm_link" />
        <!-- <origin rpy="0.0 -1.57079632679 0.0" xyz="0.0 -0.1197 0.425" /> -->
        <origin rpy="0.0 0.0 0.0" xyz="0.0 -0.1197 0.425" />
        <axis xyz="0 1 0" />
        <limit effort="150.0" lower="-6.2831853" upper="6.2831853" velocity="3.15" />
        <dynamics damping="0.0" friction="0.0" />
    </joint>
    <link name="right_forearm_link">
        <visual>
            <geometry>
                <mesh filename="package://ur_description/meshes/ur5/visual/forearm.dae" />
            </geometry>
            <material name="LightGrey">
                <color rgba="0.7 0.7 0.7 1.0" />
            </material>
        </visual>
        <collision>
            <geometry>
                <mesh filename="package://ur_description/meshes/ur5/collision/forearm.stl" />
            </geometry>
        </collision>
        <inertial>
            <mass value="2.275" />
            <!-- <origin rpy="0 0 0" xyz="0.0 0.0 0.25" /> -->
            <origin rpy="0.0 0.0 0.0" xyz="0.0 0.0265 0.11993" />
            <inertia ixx="0.049443313556" ixy="0.0" ixz="0.0" iyy="0.049443313556" iyz="0.0"
                izz="0.004095" />
        </inertial>
    </link>
    <joint name="right_wrist_1_joint" type="revolute">
        <parent link="right_forearm_link" />
        <child link="right_wrist_1_link" />
        <origin rpy="0.0 1.57079632679 0.0" xyz="0.0 0.0 0.39225" />
        <axis xyz="0 1 0" />
        <limit effort="28.0" lower="-6.2831853" upper="6.2831853" velocity="3.2" />
        <dynamics damping="0.0" friction="0.0" />
    </joint>
    <link name="right_wrist_1_link">
        <visual>
            <geometry>
                <mesh filename="package://ur_description/meshes/ur5/visual/wrist1.dae" />
            </geometry>
            <material name="LightGrey">
                <color rgba="0.7 0.7 0.7 1.0" />
            </material>
        </visual>
        <collision>
            <geometry>
                <mesh filename="package://ur_description/meshes/ur5/collision/wrist1.stl" />
            </geometry>
        </collision>
        <inertial>
            <mass value="1.219" />
            <!-- <origin rpy="0 0 0" xyz="0.0 0.0 0.0" /> -->
            <origin rpy="0.0 0.0 0.0" xyz="0.0 0.110949 0.01634" />
            <inertia ixx="0.111172755531" ixy="0.0" ixz="0.0" iyy="0.111172755531" iyz="0.0"
                izz="0.21942" />
        </inertial>
    </link>
    <joint name="right_wrist_2_joint" type="revolute">
        <parent link="right_wrist_1_link" />
        <child link="right_wrist_2_link" />
        <!-- <origin rpy="0.0 0.0 -1.57079632679" xyz="0.0 0.093 0.0" /> -->
        <origin rpy="0.0 0.0 0.0" xyz="0.0 0.093 0.0" />
        <axis xyz="0 0 1" />
        <limit effort="28.0" lower="-6.2831853" upper="6.2831853" velocity="3.2" />
        <dynamics damping="0.0" friction="0.0" />
    </joint>
    <link name="right_wrist_2_link">
        <visual>
            <geometry>
                <mesh filename="package://ur_description/meshes/ur5/visual/wrist2.dae" />
            </geometry>
            <material name="LightGrey">
                <color rgba="0.7 0.7 0.7 1.0" />
            </material>
        </visual>
        <collision>
            <geometry>
                <mesh filename="package://ur_description/meshes/ur5/collision/wrist2.stl" />
            </geometry>
        </collision>
        <inertial>
            <mass value="1.219" />
            <!-- <origin rpy="0 0 0" xyz="0.0 0.0 0.0" /> -->
            <origin rpy="0.0 0.0 0.0" xyz="0.0 0.0018 0.11099" />
            <inertia ixx="0.111172755531" ixy="0.0" ixz="0.0" iyy="0.111172755531" iyz="0.0"
                izz="0.21942" />
        </inertial>
    </link>
    <joint name="right_wrist_3_joint" type="revolute">
        <parent link="right_wrist_2_link" />
        <child link="right_wrist_3_link" />
        <origin rpy="0.0 0.0 0.0" xyz="0.0 0.0 0.09465" />
        <axis xyz="0 1 0" />
        <limit effort="28.0" lower="-6.28318535" upper="6.2831853" velocity="3.2" />
        <dynamics damping="0.0" friction="0.0" />
    </joint>
    <link name="right_wrist_3_link">
        <visual>
            <geometry>
                <mesh filename="package://ur_description/meshes/ur5/visual/wrist3.dae" />
            </geometry>
            <material name="LightGrey">
                <color rgba="0.7 0.7 0.7 1.0" />
            </material>
        </visual>
        <collision>
            <geometry>
                <mesh filename="package://ur_description/meshes/ur5/collision/wrist3.stl" />
            </geometry>
        </collision>
        <inertial>
            <mass value="0.1879" />
            <!-- <origin rpy="0 0 0" xyz="0.0 0.0 0.0" /> -->
            <origin rpy="0.0 0.0 0.0" xyz="0.0 0.001159 0.0" />
            <inertia ixx="0.0171364731454" ixy="0.0" ixz="0.0" iyy="0.0171364731454" iyz="0.0"
                izz="0.033822" />
        </inertial>
    </link>
    <joint name="right_ee_fixed_joint" type="fixed">
        <parent link="right_wrist_3_link" />
        <child link="right_ee_link" />
        <origin rpy="0.0 0.0 1.57079632679" xyz="0.0 0.0823 0.0" />
    </joint>
    <link name="right_ee_link">
        <collision>
            <geometry>
                <box size="0.01 0.01 0.01" />
            </geometry>
            <origin rpy="0 0 0" xyz="-0.01 0 0" />
        </collision>
        <inertial>
            <mass value="0.1" />
            <origin xyz="0 0 0" rpy="0 0 0" />
            <inertia ixx="0.03" iyy="0.03" izz="0.03" ixy="0.0" ixz="0.0" iyz="0.0" />
        </inertial>
    </link>
    <!-- Frame coincident with all-zeros TCP on UR controller -->
    <joint name="right_arm_temp_joint" type="fixed">
        <parent link="world" />
        <child link="right_arm_temp" />
        <origin rpy="  0.78539816339 0.0 0.0" xyz="-0.06 -0.235 0.415" />
    </joint>
    <link name="right_arm_temp" />
    <joint name="right_world_joint" type="fixed">
        <parent link="right_arm_temp" />
        <child link="right_base_link" />
        <origin rpy="0.0 0.0 -2.355" xyz="-0.001 0.004 0" />
    </joint>
    <!-- body part-->
    <link name="base_link">
        <inertial>
            <origin xyz="-0.000962390959686438 0.0854841651293876 -0.0961620681936492" rpy="0 0 0" />
            <mass value="37.1209809492073" />
            <inertia ixx="0.43598678033765" ixy="-0.000423569728196321" ixz="0.00215126921879573"
                iyy="0.232442849103403" iyz="-0.0364214807289123" izz="0.517338123880074" />
        </inertial>
        <visual>
            <origin xyz="0 0 0" rpy="0 0 0" />
            <geometry>
                <mesh filename="package://ur_description/meshes/ur5/base_link.STL" />
            </geometry>
            <material name="">
                <color rgba="0.792156862745098 0.819607843137255 0.933333333333333 1" />
            </material>
        </visual>
        <collision>
            <origin xyz="0 0 0" rpy="0 0 0" />
            <geometry>
                <mesh filename="package://ur_description/meshes/ur5/base_link.STL" />
            </geometry>
        </collision>
    </link>
    <joint name="joint" type="fixed">
        <parent link="world" />
        <child link="base_link" />
        <origin rpy="0 0.0 1.57079632679" xyz="0.0 0.0 0.12" />
    </joint>
    <!--above
    is the part of robot's body -->
    <transmission name="trans_left_shoulder_pan_joint">
        <type>transmission_interface/SimpleTransmission</type>
        <joint name="left_shoulder_pan_joint">
            <hardwareInterface>hardware_interface/EffortJointInterface</hardwareInterface>
        </joint>
        <actuator name="left_shoulder_pan_joint_motor">
            <hardwareInterface>hardware_interface/EffortJointInterface</hardwareInterface>
            <mechanicalReduction>1</mechanicalReduction>
        </actuator>
    </transmission>
    <transmission name="trans_left_shoulder_lift_joint">
        <type>transmission_interface/SimpleTransmission</type>
        <joint name="left_shoulder_lift_joint">
            <hardwareInterface>hardware_interface/EffortJointInterface</hardwareInterface>
        </joint>
        <actuator name="left_shoulder_lift_joint_motor">
            <hardwareInterface>hardware_interface/EffortJointInterface</hardwareInterface>
            <mechanicalReduction>1</mechanicalReduction>
        </actuator>
    </transmission>
    <transmission name="trans_left_elbow_joint">
        <type>transmission_interface/SimpleTransmission</type>
        <joint name="left_elbow_joint">
            <hardwareInterface>hardware_interface/EffortJointInterface</hardwareInterface>
        </joint>
        <actuator name="left_elbow_joint_motor">
            <hardwareInterface>hardware_interface/EffortJointInterface</hardwareInterface>
            <mechanicalReduction>1</mechanicalReduction>
        </actuator>
    </transmission>
    <transmission name="trans_left_wrist_1_joint">
        <type>transmission_interface/SimpleTransmission</type>
        <joint name="left_wrist_1_joint">
            <hardwareInterface>hardware_interface/EffortJointInterface</hardwareInterface>
        </joint>
        <actuator name="left_wrist_1_joint_motor">
            <hardwareInterface>hardware_interface/EffortJointInterface</hardwareInterface>
            <mechanicalReduction>1</mechanicalReduction>
        </actuator>
    </transmission>
    <transmission name="trans_left_wrist_2_joint">
        <type>transmission_interface/SimpleTransmission</type>
        <joint name="left_wrist_2_joint">
            <hardwareInterface>hardware_interface/EffortJointInterface</hardwareInterface>
        </joint>
        <actuator name="left_wrist_2_joint_motor">
            <hardwareInterface>hardware_interface/EffortJointInterface</hardwareInterface>
            <mechanicalReduction>1</mechanicalReduction>
        </actuator>
    </transmission>
    <transmission name="trans_left_wrist_3_joint">
        <type>transmission_interface/SimpleTransmission</type>
        <joint name="left_wrist_3_joint">
            <hardwareInterface>hardware_interface/EffortJointInterface</hardwareInterface>
        </joint>
        <actuator name="left_wrist_3_joint_motor">
            <hardwareInterface>hardware_interface/EffortJointInterface</hardwareInterface>
            <mechanicalReduction>1</mechanicalReduction>
        </actuator>
    </transmission>
    <transmission name="trans_L_thumb_proximal_yaw_joint">
        <type>transmission_interface/SimpleTransmission</type>
        <joint name="L_thumb_proximal_yaw_joint">
            <hardwareInterface>hardware_interface/EffortJointInterface</hardwareInterface>
        </joint>
        <actuator name="L_thumb_proximal_yaw_joint_motor">
            <hardwareInterface>hardware_interface/EffortJointInterface</hardwareInterface>
            <mechanicalReduction>1</mechanicalReduction>
        </actuator>
    </transmission>
    <transmission name="trans_L_thumb_proximal_pitch_joint">
        <type>transmission_interface/SimpleTransmission</type>
        <joint name="L_thumb_proximal_pitch_joint">
            <hardwareInterface>hardware_interface/EffortJointInterface</hardwareInterface>
        </joint>
        <actuator name="L_thumb_proximal_pitch_joint_motor">
            <hardwareInterface>hardware_interface/EffortJointInterface</hardwareInterface>
            <mechanicalReduction>1</mechanicalReduction>
        </actuator>
    </transmission>
    <transmission name="trans_L_thumb_intermediate_joint">
        <type>transmission_interface/SimpleTransmission</type>
        <joint name="L_thumb_intermediate_joint">
            <hardwareInterface>hardware_interface/EffortJointInterface</hardwareInterface>
        </joint>
        <actuator name="L_thumb_intermediate_joint_motor">
            <hardwareInterface>hardware_interface/EffortJointInterface</hardwareInterface>
            <mechanicalReduction>1</mechanicalReduction>
        </actuator>
    </transmission>
    <transmission name="trans_L_thumb_distal_joint">
        <type>transmission_interface/SimpleTransmission</type>
        <joint name="L_thumb_distal_joint">
            <hardwareInterface>hardware_interface/EffortJointInterface</hardwareInterface>
        </joint>
        <actuator name="L_thumb_distal_joint_motor">
            <hardwareInterface>hardware_interface/EffortJointInterface</hardwareInterface>
            <mechanicalReduction>1</mechanicalReduction>
        </actuator>
    </transmission>
    <transmission name="trans_L_index_proximal_joint">
        <type>transmission_interface/SimpleTransmission</type>
        <joint name="L_index_proximal_joint">
            <hardwareInterface>hardware_interface/EffortJointInterface</hardwareInterface>
        </joint>
        <actuator name="L_index_proximal_joint_motor">
            <hardwareInterface>hardware_interface/EffortJointInterface</hardwareInterface>
            <mechanicalReduction>1</mechanicalReduction>
        </actuator>
    </transmission>
    <transmission name="trans_L_index_intermediate_joint">
        <type>transmission_interface/SimpleTransmission</type>
        <joint name="L_index_intermediate_joint">
            <hardwareInterface>hardware_interface/EffortJointInterface</hardwareInterface>
        </joint>
        <actuator name="L_index_intermediate_joint_motor">
            <hardwareInterface>hardware_interface/EffortJointInterface</hardwareInterface>
            <mechanicalReduction>1</mechanicalReduction>
        </actuator>
    </transmission>
    <transmission name="trans_L_middle_proximal_joint">
        <type>transmission_interface/SimpleTransmission</type>
        <joint name="L_middle_proximal_joint">
            <hardwareInterface>hardware_interface/EffortJointInterface</hardwareInterface>
        </joint>
        <actuator name="L_middle_proximal_joint_motor">
            <hardwareInterface>hardware_interface/EffortJointInterface</hardwareInterface>
            <mechanicalReduction>1</mechanicalReduction>
        </actuator>
    </transmission>
    <transmission name="trans_L_middle_intermediate_joint">
        <type>transmission_interface/SimpleTransmission</type>
        <joint name="L_middle_intermediate_joint">
            <hardwareInterface>hardware_interface/EffortJointInterface</hardwareInterface>
        </joint>
        <actuator name="L_middle_intermediate_joint_motor">
            <hardwareInterface>hardware_interface/EffortJointInterface</hardwareInterface>
            <mechanicalReduction>1</mechanicalReduction>
        </actuator>
    </transmission>
    <transmission name="trans_L_ring_proximal_joint">
        <type>transmission_interface/SimpleTransmission</type>
        <joint name="L_ring_proximal_joint">
            <hardwareInterface>hardware_interface/EffortJointInterface</hardwareInterface>
        </joint>
        <actuator name="L_ring_proximal_joint_motor">
            <hardwareInterface>hardware_interface/EffortJointInterface</hardwareInterface>
            <mechanicalReduction>1</mechanicalReduction>
        </actuator>
    </transmission>
    <transmission name="trans_L_ring_intermediate_joint">
        <type>transmission_interface/SimpleTransmission</type>
        <joint name="L_ring_intermediate_joint">
            <hardwareInterface>hardware_interface/EffortJointInterface</hardwareInterface>
        </joint>
        <actuator name="L_ring_intermediate_joint_motor">
            <hardwareInterface>hardware_interface/EffortJointInterface</hardwareInterface>
            <mechanicalReduction>1</mechanicalReduction>
        </actuator>
    </transmission>
    <transmission name="trans_L_pinky_proximal_joint">
        <type>transmission_interface/SimpleTransmission</type>
        <joint name="L_pinky_proximal_joint">
            <hardwareInterface>hardware_interface/EffortJointInterface</hardwareInterface>
        </joint>
        <actuator name="L_pinky_proximal_joint_motor">
            <hardwareInterface>hardware_interface/EffortJointInterface</hardwareInterface>
            <mechanicalReduction>1</mechanicalReduction>
        </actuator>
    </transmission>
    <transmission name="trans_L_pinky_intermediate_joint">
        <type>transmission_interface/SimpleTransmission</type>
        <joint name="L_pinky_intermediate_joint">
            <hardwareInterface>hardware_interface/EffortJointInterface</hardwareInterface>
        </joint>
        <actuator name="L_pinky_intermediate_joint_motor">
            <hardwareInterface>hardware_interface/EffortJointInterface</hardwareInterface>
            <mechanicalReduction>1</mechanicalReduction>
        </actuator>
    </transmission>
    <transmission name="trans_right_shoulder_pan_joint">
        <type>transmission_interface/SimpleTransmission</type>
        <joint name="right_shoulder_pan_joint">
            <hardwareInterface>hardware_interface/EffortJointInterface</hardwareInterface>
        </joint>
        <actuator name="right_shoulder_pan_joint_motor">
            <hardwareInterface>hardware_interface/EffortJointInterface</hardwareInterface>
            <mechanicalReduction>1</mechanicalReduction>
        </actuator>
    </transmission>
    <transmission name="trans_right_shoulder_lift_joint">
        <type>transmission_interface/SimpleTransmission</type>
        <joint name="right_shoulder_lift_joint">
            <hardwareInterface>hardware_interface/EffortJointInterface</hardwareInterface>
        </joint>
        <actuator name="right_shoulder_lift_joint_motor">
            <hardwareInterface>hardware_interface/EffortJointInterface</hardwareInterface>
            <mechanicalReduction>1</mechanicalReduction>
        </actuator>
    </transmission>
    <transmission name="trans_right_elbow_joint">
        <type>transmission_interface/SimpleTransmission</type>
        <joint name="right_elbow_joint">
            <hardwareInterface>hardware_interface/EffortJointInterface</hardwareInterface>
        </joint>
        <actuator name="right_elbow_joint_motor">
            <hardwareInterface>hardware_interface/EffortJointInterface</hardwareInterface>
            <mechanicalReduction>1</mechanicalReduction>
        </actuator>
    </transmission>
    <transmission name="trans_right_wrist_1_joint">
        <type>transmission_interface/SimpleTransmission</type>
        <joint name="right_wrist_1_joint">
            <hardwareInterface>hardware_interface/EffortJointInterface</hardwareInterface>
        </joint>
        <actuator name="right_wrist_1_joint_motor">
            <hardwareInterface>hardware_interface/EffortJointInterface</hardwareInterface>
            <mechanicalReduction>1</mechanicalReduction>
        </actuator>
    </transmission>
    <transmission name="trans_right_wrist_2_joint">
        <type>transmission_interface/SimpleTransmission</type>
        <joint name="right_wrist_2_joint">
            <hardwareInterface>hardware_interface/EffortJointInterface</hardwareInterface>
        </joint>
        <actuator name="right_wrist_2_joint_motor">
            <hardwareInterface>hardware_interface/EffortJointInterface</hardwareInterface>
            <mechanicalReduction>1</mechanicalReduction>
        </actuator>
    </transmission>
    <transmission name="trans_right_wrist_3_joint">
        <type>transmission_interface/SimpleTransmission</type>
        <joint name="right_wrist_3_joint">
            <hardwareInterface>hardware_interface/EffortJointInterface</hardwareInterface>
        </joint>
        <actuator name="right_wrist_3_joint_motor">
            <hardwareInterface>hardware_interface/EffortJointInterface</hardwareInterface>
            <mechanicalReduction>1</mechanicalReduction>
        </actuator>
    </transmission>
    <transmission name="trans_R_thumb_proximal_yaw_joint">
        <type>transmission_interface/SimpleTransmission</type>
        <joint name="R_thumb_proximal_yaw_joint">
            <hardwareInterface>hardware_interface/EffortJointInterface</hardwareInterface>
        </joint>
        <actuator name="R_thumb_proximal_yaw_joint_motor">
            <hardwareInterface>hardware_interface/EffortJointInterface</hardwareInterface>
            <mechanicalReduction>1</mechanicalReduction>
        </actuator>
    </transmission>
    <transmission name="trans_R_thumb_proximal_pitch_joint">
        <type>transmission_interface/SimpleTransmission</type>
        <joint name="R_thumb_proximal_pitch_joint">
            <hardwareInterface>hardware_interface/EffortJointInterface</hardwareInterface>
        </joint>
        <actuator name="R_thumb_proximal_pitch_joint_motor">
            <hardwareInterface>hardware_interface/EffortJointInterface</hardwareInterface>
            <mechanicalReduction>1</mechanicalReduction>
        </actuator>
    </transmission>
    <transmission name="trans_R_thumb_intermediate_joint">
        <type>transmission_interface/SimpleTransmission</type>
        <joint name="R_thumb_intermediate_joint">
            <hardwareInterface>hardware_interface/EffortJointInterface</hardwareInterface>
        </joint>
        <actuator name="R_thumb_intermediate_joint_motor">
            <hardwareInterface>hardware_interface/EffortJointInterface</hardwareInterface>
            <mechanicalReduction>1</mechanicalReduction>
        </actuator>
    </transmission>
    <transmission name="trans_R_thumb_distal_joint">
        <type>transmission_interface/SimpleTransmission</type>
        <joint name="R_thumb_distal_joint">
            <hardwareInterface>hardware_interface/EffortJointInterface</hardwareInterface>
        </joint>
        <actuator name="R_thumb_distal_joint_motor">
            <hardwareInterface>hardware_interface/EffortJointInterface</hardwareInterface>
            <mechanicalReduction>1</mechanicalReduction>
        </actuator>
    </transmission>
    <transmission name="trans_R_index_proximal_joint">
        <type>transmission_interface/SimpleTransmission</type>
        <joint name="R_index_proximal_joint">
            <hardwareInterface>hardware_interface/EffortJointInterface</hardwareInterface>
        </joint>
        <actuator name="R_index_proximal_joint_motor">
            <hardwareInterface>hardware_interface/EffortJointInterface</hardwareInterface>
            <mechanicalReduction>1</mechanicalReduction>
        </actuator>
    </transmission>
    <transmission name="trans_R_index_intermediate_joint">
        <type>transmission_interface/SimpleTransmission</type>
        <joint name="R_index_intermediate_joint">
            <hardwareInterface>hardware_interface/EffortJointInterface</hardwareInterface>
        </joint>
        <actuator name="R_index_intermediate_joint_motor">
            <hardwareInterface>hardware_interface/EffortJointInterface</hardwareInterface>
            <mechanicalReduction>1</mechanicalReduction>
        </actuator>
    </transmission>
    <transmission name="trans_R_middle_proximal_joint">
        <type>transmission_interface/SimpleTransmission</type>
        <joint name="R_middle_proximal_joint">
            <hardwareInterface>hardware_interface/EffortJointInterface</hardwareInterface>
        </joint>
        <actuator name="R_middle_proximal_joint_motor">
            <hardwareInterface>hardware_interface/EffortJointInterface</hardwareInterface>
            <mechanicalReduction>1</mechanicalReduction>
        </actuator>
    </transmission>
    <transmission name="trans_R_middle_intermediate_joint">
        <type>transmission_interface/SimpleTransmission</type>
        <joint name="R_middle_intermediate_joint">
            <hardwareInterface>hardware_interface/EffortJointInterface</hardwareInterface>
        </joint>
        <actuator name="R_middle_intermediate_joint_motor">
            <hardwareInterface>hardware_interface/EffortJointInterface</hardwareInterface>
            <mechanicalReduction>1</mechanicalReduction>
        </actuator>
    </transmission>
    <transmission name="trans_R_ring_proximal_joint">
        <type>transmission_interface/SimpleTransmission</type>
        <joint name="R_ring_proximal_joint">
            <hardwareInterface>hardware_interface/EffortJointInterface</hardwareInterface>
        </joint>
        <actuator name="R_ring_proximal_joint_motor">
            <hardwareInterface>hardware_interface/EffortJointInterface</hardwareInterface>
            <mechanicalReduction>1</mechanicalReduction>
        </actuator>
    </transmission>
    <transmission name="trans_R_ring_intermediate_joint">
        <type>transmission_interface/SimpleTransmission</type>
        <joint name="R_ring_intermediate_joint">
            <hardwareInterface>hardware_interface/EffortJointInterface</hardwareInterface>
        </joint>
        <actuator name="R_ring_intermediate_joint_motor">
            <hardwareInterface>hardware_interface/EffortJointInterface</hardwareInterface>
            <mechanicalReduction>1</mechanicalReduction>
        </actuator>
    </transmission>
    <transmission name="trans_R_pinky_proximal_joint">
        <type>transmission_interface/SimpleTransmission</type>
        <joint name="R_pinky_proximal_joint">
            <hardwareInterface>hardware_interface/EffortJointInterface</hardwareInterface>
        </joint>
        <actuator name="R_pinky_proximal_joint_motor">
            <hardwareInterface>hardware_interface/EffortJointInterface</hardwareInterface>
            <mechanicalReduction>1</mechanicalReduction>
        </actuator>
    </transmission>
    <transmission name="trans_R_pinky_intermediate_joint">
        <type>transmission_interface/SimpleTransmission</type>
        <joint name="R_pinky_intermediate_joint">
            <hardwareInterface>hardware_interface/EffortJointInterface</hardwareInterface>
        </joint>
        <actuator name="R_pinky_intermediate_joint_motor">
            <hardwareInterface>hardware_interface/EffortJointInterface</hardwareInterface>
            <mechanicalReduction>1</mechanicalReduction>
        </actuator>
    </transmission>
    <!-- <gazebo>
        <plugin name="L_thumb_intermediate_joint" filename="libroboticsgroup_gazebo_mimic_joint_plugin.so">
            <joint>L_thumb_intermediate_joint</joint>
            <mimicJoint>L_thumb_proximal_pitch_joint</mimicJoint>
            <multiplier>1.6</multiplier>
        </plugin>
        <plugin name="L_thumb_distal_joint" filename="libroboticsgroup_gazebo_mimic_joint_plugin.so">
            <joint>L_thumb_distal_joint</joint>
            <mimicJoint>L_thumb_proximal_pitch_joint</mimicJoint>
            <multiplier>2.4</multiplier>
        </plugin>
        <plugin name="L_index_intermediate_joint" filename="libroboticsgroup_gazebo_mimic_joint_plugin.so">
            <joint>L_index_intermediate_joint</joint>
            <mimicJoint>L_index_proximal_joint</mimicJoint>
            <multiplier>1</multiplier>
        </plugin>
        <plugin name="L_middle_intermediate_joint"
    filename="libroboticsgroup_gazebo_mimic_joint_plugin.so">
            <joint>L_middle_intermediate_joint</joint>
            <mimicJoint>L_middle_proximal_joint</mimicJoint>
            <multiplier>1</multiplier>
        </plugin>
        <plugin name="L_ring_intermediate_joint" filename="libroboticsgroup_gazebo_mimic_joint_plugin.so">
            <joint>L_ring_intermediate_joint</joint>
            <mimicJoint>L_ring_proximal_joint</mimicJoint>
            <multiplier>1</multiplier>
        </plugin>
        <plugin name="L_pinky_intermediate_joint" filename="libroboticsgroup_gazebo_mimic_joint_plugin.so">
            <joint>L_pinky_intermediate_joint</joint>
            <mimicJoint>L_pinky_proximal_joint</mimicJoint>
            <multiplier>1</multiplier>
        </plugin>
        <plugin name="R_thumb_intermediate_joint" filename="libroboticsgroup_gazebo_mimic_joint_plugin.so">
            <joint>R_thumb_intermediate_joint</joint>
            <mimicJoint>R_thumb_proximal_pitch_joint</mimicJoint>
            <multiplier>1.6</multiplier>
        </plugin>
        <plugin name="R_thumb_distal_joint" filename="libroboticsgroup_gazebo_mimic_joint_plugin.so">
            <joint>R_thumb_distal_joint</joint>
            <mimicJoint>R_thumb_proximal_pitch_joint</mimicJoint>
            <multiplier>2.4</multiplier>
        </plugin>
        <plugin name="R_index_intermediate_joint" filename="libroboticsgroup_gazebo_mimic_joint_plugin.so">
            <joint>R_index_intermediate_joint</joint>
            <mimicJoint>R_index_proximal_joint</mimicJoint>
            <multiplier>1</multiplier>
        </plugin>
        <plugin name="R_middle_intermediate_joint"
    filename="libroboticsgroup_gazebo_mimic_joint_plugin.so">
            <joint>R_middle_intermediate_joint</joint>
            <mimicJoint>R_middle_proximal_joint</mimicJoint>
            <multiplier>1</multiplier>
        </plugin>
        <plugin name="R_ring_intermediate_joint" filename="libroboticsgroup_gazebo_mimic_joint_plugin.so">
            <joint>R_ring_intermediate_joint</joint>
            <mimicJoint>R_ring_proximal_joint</mimicJoint>
            <multiplier>1</multiplier>
        </plugin>
        <plugin name="R_pinky_intermediate_joint" filename="libroboticsgroup_gazebo_mimic_joint_plugin.so">
            <joint>R_pinky_intermediate_joint</joint>
            <mimicJoint>R_pinky_proximal_joint</mimicJoint>
            <multiplier>1</multiplier>
        </plugin>
    </gazebo> -->
</robot>
