<?xml version="1.0"?>
<!-- =================================================================================== -->
<!-- |    This document was autogenerated by xacro from ur5_robot.urdf.xacro           | -->
<!-- |    EDITING THIS FILE BY HAND IS NOT RECOMMENDED                                 | -->
<!-- =================================================================================== -->
<robot name="ur5" xmlns:xacro="http://wiki.ros.org/xacro">
    <!-- This is the sign-language robot's description file, with two ur5 arms and two
    inspire-hands. -->
    <!-- Add mimic joint plugin for the gripper -->
    <!--gazebo>
    <!- - left gripper's mimic joints- ->
    <plugin name="MimicJointPlugin_left_rh_r2"
    filename="libroboticsgroup_gazebo_mimic_joint_plugin.so">
      <joint>left_rh_p12_rn</joint>
      <mimicJoint>left_rh_r2</mimicJoint>
      <multiplier>0.9090909</multiplier>
    </plugin>
    <plugin name="MimicJointPlugin_left_rh_l1"
    filename="libroboticsgroup_gazebo_mimic_joint_plugin.so">
      <joint>left_rh_p12_rn</joint>
      <mimicJoint>left_rh_l1</mimicJoint>
      <multiplier>1.0</multiplier>
    </plugin>
    <plugin name="MimicJointPlugin_left_rh_l2"
    filename="libroboticsgroup_gazebo_mimic_joint_plugin.so">
      <joint>left_rh_p12_rn</joint>
      <mimicJoint>left_rh_l2</mimicJoint>
      <multiplier>0.9090909</multiplier>
    </plugin>

    <!- - right gripper's mimic joints- ->
    <plugin name="MimicJointPlugin_right_rh_r2"
    filename="libroboticsgroup_gazebo_mimic_joint_plugin.so">
      <joint>right_rh_p12_rn</joint>
      <mimicJoint>right_rh_r2</mimicJoint>
      <multiplier>0.9090909</multiplier>
    </plugin>
    <plugin name="MimicJointPlugin_right_rh_l1"
    filename="libroboticsgroup_gazebo_mimic_joint_plugin.so">
      <joint>right_rh_p12_rn</joint>
      <mimicJoint>right_rh_l1</mimicJoint>
      <multiplier>1.0</multiplier>
    </plugin>
    <plugin name="MimicJointPlugin_right_rh_l2"
    filename="libroboticsgroup_gazebo_mimic_joint_plugin.so">
      <joint>right_rh_p12_rn</joint>
      <mimicJoint>right_rh_l2</mimicJoint>
      <multiplier>0.9090909</multiplier>
    </plugin>
  </gazebo-->
    <!--
    <plugin name="gazebo_ros_power_monitor_controller" filename="libgazebo_ros_power_monitor.so">
      <alwaysOn>true</alwaysOn>
      <updateRate>1.0</updateRate>
      <timeout>5</timeout>
      <powerStateTopic>power_state</powerStateTopic>
      <powerStateRate>10.0</powerStateRate>
      <fullChargeCapacity>87.78</fullChargeCapacity>
      <dischargeRate>-474</dischargeRate>
      <chargeRate>525</chargeRate>
      <dischargeVoltage>15.52</dischargeVoltage>
      <chargeVoltage>16.41</chargeVoltage>
    </plugin>
-->
    <gazebo>
        <plugin name="gazebo_ros_control" filename="libgazebo_ros_control.so">
            <robotNamespace>/</robotNamespace>
        </plugin>
    </gazebo>
    <!-- measured from model -->
    <!--property
    name="shoulder_height" value="0.089159" /-->
    <!--property
    name="shoulder_offset" value="0.13585" /-->
    <!-- shoulder_offset - elbow_offset + wrist_1_length = 0.10915 -->
    <!--property
    name="upper_arm_length" value="0.42500" /-->
    <!--property
    name="elbow_offset" value="0.1197" /-->
    <!-- CAD measured -->
    <!--property
    name="forearm_length" value="0.39225" /-->
    <!--property
    name="wrist_1_length" value="0.093" /-->
    <!-- CAD measured -->
    <!--property
    name="wrist_2_length" value="0.09465" /-->
    <!-- In CAD this distance is 0.930, but in the spec it is 0.09465 -->
    <!--property
    name="wrist_3_length" value="0.0823" /-->
    <!-- manually measured -->
    <link name="left_base_link">
        <visual>
            <geometry>
                <mesh filename="package://ur_description/meshes/ur5/visual/base.dae" />
            </geometry>
            <material name="LightGrey">
                <color rgba="0.7 0.7 0.7 1.0" />
            </material>
        </visual>
        <collision>
            <geometry>
                <mesh filename="package://ur_description/meshes/ur5/collision/base.stl" />
            </geometry>
        </collision>
        <inertial>
            <mass value="4.0" />
            <origin rpy="0 0 0" xyz="0.0 0.0 0.0" />
            <inertia ixx="0.00443333156" ixy="0.0" ixz="0.0" iyy="0.00443333156" iyz="0.0"
                izz="0.0072" />
        </inertial>
    </link>
    <joint name="left_shoulder_pan_joint" type="revolute">
        <parent link="left_base_link" />
        <child link="left_shoulder_link" />
        <origin rpy="0.0 0.0 0.0" xyz="0.0 0.0 0.089159" />
        <axis xyz="0 0 1" />
        <limit effort="150.0" lower="-6.28318530718" upper="6.28318530718" velocity="3.15" />
        <dynamics damping="0.0" friction="0.0" />
    </joint>
    <link name="left_shoulder_link">
        <visual>
            <geometry>
                <mesh filename="package://ur_description/meshes/ur5/visual/shoulder.dae" />
            </geometry>
            <material name="LightGrey">
                <color rgba="0.7 0.7 0.7 1.0" />
            </material>
        </visual>
        <collision>
            <geometry>
                <mesh filename="package://ur_description/meshes/ur5/collision/shoulder.stl" />
            </geometry>
        </collision>
        <inertial>
            <mass value="3.7" />
            <!-- <origin rpy="0 0 0" xyz="0.0 0.0 0.0" /> -->
            <origin rpy="0.0 0.0 0.0" xyz="0.0 0.00193 -0.02561" />
            <inertia ixx="0.010267495893" ixy="0.0" ixz="0.0" iyy="0.010267495893" iyz="0.0"
                izz="0.00666" />
        </inertial>
    </link>
    <joint name="left_shoulder_lift_joint" type="revolute">
        <parent link="left_shoulder_link" />
        <child link="left_upper_arm_link" />
        <!-- <origin rpy="0.0 0.78539816339 0.0" xyz="0.0 0.13585 0.0" /> -->
        <origin rpy="0.0 1.570796325 0.0" xyz="0.0 0.13585 0.0" />
        <axis xyz="0 1 0" />
        <limit effort="150.0" lower="-6.2831853" upper="6.2831853" velocity="3.15" />
        <dynamics damping="0.0" friction="0.0" />
    </joint>
    <link name="left_upper_arm_link">
        <visual>
            <geometry>
                <mesh filename="package://ur_description/meshes/ur5/visual/upperarm.dae" />
            </geometry>
            <material name="LightGrey">
                <color rgba="0.7 0.7 0.7 1.0" />
            </material>
        </visual>
        <collision>
            <geometry>
                <mesh filename="package://ur_description/meshes/ur5/collision/upperarm.stl" />
            </geometry>
        </collision>
        <inertial>
            <mass value="8.393" />
            <!-- <origin rpy="0 0 0" xyz="0.0 0.0 0.28" /> -->
            <origin rpy="0.0 0.0 0.0" xyz="0.0 -0.024201 0.2125" />
            <inertia ixx="0.22689067591" ixy="0.0" ixz="0.0" iyy="0.22689067591" iyz="0.0"
                izz="0.0151074" />
        </inertial>
    </link>
    <joint name="left_elbow_joint" type="revolute">
        <parent link="left_upper_arm_link" />
        <child link="left_forearm_link" />
        <!-- <origin rpy="0.0 1.57079632679 0.0" xyz="0.0 -0.1197 0.425" /> -->
        <origin rpy="0.0 0.0 0.0" xyz="0.0 -0.1197 0.425" />
        <axis xyz="0 1 0" />
        <limit effort="150.0" lower="-6.2831853" upper="6.2831853" velocity="3.15" />
        <dynamics damping="0.0" friction="0.0" />
    </joint>
    <link name="left_forearm_link">
        <visual>
            <geometry>
                <mesh filename="package://ur_description/meshes/ur5/visual/forearm.dae" />
            </geometry>
            <material name="LightGrey">
                <color rgba="0.7 0.7 0.7 1.0" />
            </material>
        </visual>
        <collision>
            <geometry>
                <mesh filename="package://ur_description/meshes/ur5/collision/forearm.stl" />
            </geometry>
        </collision>
        <inertial>
            <mass value="2.275" />
            <!-- <origin rpy="0 0 0" xyz="0.0 0.0 0.25" /> -->
            <origin rpy="0.0 0.0 0.0" xyz="0.0 0.0265 0.11993" />
            <inertia ixx="0.049443313556" ixy="0.0" ixz="0.0" iyy="0.049443313556" iyz="0.0"
                izz="0.004095" />
        </inertial>
    </link>
    <joint name="left_wrist_1_joint" type="revolute">
        <parent link="left_forearm_link" />
        <child link="left_wrist_1_link" />
        <origin rpy="0.0 1.57079632679 0.0" xyz="0.0 0.0 0.39225" />
        <axis xyz="0 1 0" />
        <limit effort="28.0" lower="-6.2831853" upper="6.2831853" velocity="3.14159265" />
        <dynamics damping="0.0" friction="0.0" />
    </joint>
    <link name="left_wrist_1_link">
        <visual>
            <geometry>
                <mesh filename="package://ur_description/meshes/ur5/visual/wrist1.dae" />
            </geometry>
            <material name="LightGrey">
                <color rgba="0.7 0.7 0.7 1.0" />
            </material>
        </visual>
        <collision>
            <geometry>
                <mesh filename="package://ur_description/meshes/ur5/collision/wrist1.stl" />
            </geometry>
        </collision>
        <inertial>
            <mass value="1.219" />
            <!-- <origin rpy="0 0 0" xyz="0.0 0.0 0.0" /> -->
            <origin rpy="0.0 0.0 0.0" xyz="0.0 0.110949 0.01634" />
            <inertia ixx="0.111172755531" ixy="0.0" ixz="0.0" iyy="0.111172755531" iyz="0.0"
                izz="0.21942" />
        </inertial>
    </link>
    <joint name="left_wrist_2_joint" type="revolute">
        <parent link="left_wrist_1_link" />
        <child link="left_wrist_2_link" />
        <!-- <origin rpy="0.0 0.0 1.57079632679" xyz="0.0 0.093 0.0" /> -->
        <origin rpy="0.0 0.0 0.0" xyz="0.0 0.093 0.0" />
        <axis xyz="0 0 1" />
        <limit effort="28.0" lower="-6.2831853" upper="6.2831853" velocity="3.2" />
        <dynamics damping="0.0" friction="0.0" />
    </joint>
    <link name="left_wrist_2_link">
        <visual>
            <geometry>
                <mesh filename="package://ur_description/meshes/ur5/visual/wrist2.dae" />
            </geometry>
            <material name="LightGrey">
                <color rgba="0.7 0.7 0.7 1.0" />
            </material>
        </visual>
        <collision>
            <geometry>
                <mesh filename="package://ur_description/meshes/ur5/collision/wrist2.stl" />
            </geometry>
        </collision>
        <inertial>
            <mass value="1.219" />
            <!-- <origin rpy="0 0 0" xyz="0.0 0.0 0.0" /> -->
            <origin rpy="0.0 0.0 0.0" xyz="0.0 0.0018 0.11099" />
            <inertia ixx="0.111172755531" ixy="0.0" ixz="0.0" iyy="0.111172755531" iyz="0.0"
                izz="0.21942" />
        </inertial>
    </link>
    <joint name="left_wrist_3_joint" type="revolute">
        <parent link="left_wrist_2_link" />
        <child link="left_wrist_3_link" />
        <origin rpy="0.0 0.0 0.0" xyz="0.0 0.0 0.09465" />
        <axis xyz="0 1 0" />
        <limit effort="28.0" lower="-6.2831853" upper="6.2831853" velocity="3.2" />
        <dynamics damping="0.0" friction="0.0" />
    </joint>
    <link name="left_wrist_3_link">
        <visual>
            <geometry>
                <mesh filename="package://ur_description/meshes/ur5/visual/wrist3.dae" />
            </geometry>
            <material name="LightGrey">
                <color rgba="0.7 0.7 0.7 1.0" />
            </material>
        </visual>
        <collision>
            <geometry>
                <mesh filename="package://ur_description/meshes/ur5/collision/wrist3.stl" />
            </geometry>
        </collision>
        <inertial>
            <mass value="0.1879" />
            <!-- <origin rpy="0 0 0" xyz="0.0 0.0 0.0" /> -->
            <origin rpy="0.0 0.0 0.0" xyz="0.0 0.001159 0.0" />
            <inertia ixx="0.0171364731454" ixy="0.0" ixz="0.0" iyy="0.0171364731454" iyz="0.0"
                izz="0.033822" />
        </inertial>
    </link>
    <joint name="left_ee_fixed_joint" type="fixed">
        <parent link="left_wrist_3_link" />
        <child link="left_ee_link" />
        <origin rpy="0.0 0.0 1.57079632679" xyz="0.0 0.0823 0.0" />
    </joint>
    <link name="left_ee_link">
        <collision>
            <geometry>
                <box size="0.01 0.01 0.01" />
            </geometry>
            <origin rpy="0 0 0" xyz="-0.01 0 0" />
        </collision>
        <inertial>
            <mass value="0.1" />
            <origin xyz="0 0 0" rpy="0 0 0" />
            <inertia ixx="0.03" iyy="0.03" izz="0.03" ixy="0.0" ixz="0.0" iyz="0.0" />
        </inertial>
    </link>
    <!-- <joint name="L_hand_base_joint" type="fixed">
        <origin xyz="-0.017 0.0 0.0" rpy="0 -2.355 1.5714" />
        <parent link="left_ee_link" />
        <child link="L_hand_base_link" />
    </joint> -->
    <!-- <link name="L_flange">
      <visual>
        <origin xyz="0 0 0" rpy="0 0 0"/>
        <geometry>
          <mesh filename="package://inspire_hand_description/meshes/left/flange.STL" scale="0.001 0.001
    0.001"/>
        </geometry>
        <material name="">
          <color rgba="1 1 1 1" />
        </material>
      </visual>
      <collision>
        <origin xyz="0 0 0" rpy="0 0 0"/>
        <geometry>
          <mesh filename="package://inspire_hand_description/meshes/left/flange.STL" scale="0.001 0.001
    0.001"/>
        </geometry>
      </collision>
      <inertial>
        <origin
          xyz="0 0 0"
          rpy="0 0 0" />
        <mass
          value="1.0372398E-01" />
        <inertia
          ixx="8.6985265E-05"
          ixy="0"
          ixz="2.7728445E-07"
          iyy="8.7567207E-05"
          iyz="6.8674339E-07"
          izz="7.4487068E-05"/>
      </inertial>
    </link> -->
    <!-- <joint
      name="L_base_link_joint"
      type="fixed">
      <origin
      xyz="0 0 0"
      rpy="1.570796 0 0" />
      <parent link="L_flange"/>
      <child link="L_hand_base_link"/>
    </joint> -->
    <!-- <link name="L_hand_base_link">
        <inertial>
            <origin xyz="-0.002551 -0.066047 -0.0019357" rpy="0 0 0" />
            <mass value="0.14143" />
            <inertia ixx="0.0001234" ixy="2.1995E-06" ixz="-1.7694E-06" iyy="8.3835E-05"
                iyz="1.5968E-06" izz="7.7231E-05" />
        </inertial>
        <visual>
            <origin xyz="0 0 0" rpy="0 0 0" />
            <geometry>
                <mesh filename="package://inspire_hand_description/meshes/left/base_link.STL" />
            </geometry>
            <material name="">
                <color rgba="1 1 1 1" />
            </material>
        </visual>
        <collision>
            <origin xyz="0 0 0" rpy="0 0 0" />
            <geometry>
                <mesh filename="package://inspire_hand_description/meshes/left/base_link.STL" />
            </geometry>
        </collision>
    </link> -->
    <link name="L_thumb_proximal_base">
        <inertial>
            <origin xyz="0.0048817 0.00038782 -0.00722" rpy="0 0 0" />
            <mass value="0.1" />
            <inertia ixx="0.1" ixy="0" ixz="0" iyy="0.1" iyz="0" izz="0.1" />
            <!-- <mass value="0.0018869" />
            <inertia ixx="5.5158E-08" ixy="-1.1803E-08" ixz="-4.6743E-09" iyy="8.2164E-08" iyz="-1.3521E-09"
            izz="6.7434E-08" /> -->
        </inertial>
        <visual>
            <origin xyz="0 0 0" rpy="0 0 0" />
            <geometry>
                <mesh filename="package://inspire_hand_description/meshes/left/Link11.STL" />
            </geometry>
            <material name="">
                <color rgba="0.82745 0.83922 0.82745 1" />
            </material>
        </visual>
        <collision>
            <origin xyz="0 0 0" rpy="0 0 0" />
            <geometry>
                <mesh filename="package://inspire_hand_description/meshes/left/Link11.STL" />
            </geometry>
        </collision>
    </link>
    <joint name="L_thumb_proximal_yaw_joint" type="revolute">
        <origin xyz="-0.01696 -0.0691 0.02045" rpy="1.5708 -1.5708 0" />
        <parent link="L_hand_base_link" />
        <child link="L_thumb_proximal_base" />
        <axis xyz="0 0 1" />
        <limit lower="-0.1" upper="1.3" effort="1" velocity="0.5" />
    </joint>
    <link name="L_thumb_proximal">
        <inertial>
            <origin xyz="0.021936 -0.01279 -0.0080386" rpy="0 0 0" />
            <mass value="0.1" />
            <inertia ixx="0.1" ixy="0" ixz="0" iyy="0.1" iyz="0" izz="0.1" />
            <!-- <mass value="0.0066101" />
            <inertia ixx="1.5693E-06" ixy="7.8339E-07" ixz="8.5959E-10" iyy="1.7356E-06" iyz="1.0378E-09"
            izz="2.787E-06" /> -->
        </inertial>
        <visual>
            <origin xyz="0 0 0" rpy="0 0 0" />
            <geometry>
                <mesh filename="package://inspire_hand_description/meshes/left/Link12.STL" />
            </geometry>
            <material name="">
                <color rgba="1 1 1 1" />
            </material>
        </visual>
        <collision>
            <origin xyz="0 0 0" rpy="0 0 0" />
            <geometry>
                <mesh filename="package://inspire_hand_description/meshes/left/Link12.STL" />
            </geometry>
        </collision>
    </link>
    <joint name="L_thumb_proximal_pitch_joint" type="revolute">
        <origin xyz="0.0099867 0.0098242 -0.0089" rpy="-1.5708 0 0.16939" />
        <parent link="L_thumb_proximal_base" />
        <child link="L_thumb_proximal" />
        <axis xyz="0 0 -1" />
        <limit lower="-0.1" upper="0.6" effort="1" velocity="0.5" />
    </joint>
    <link name="L_thumb_intermediate">
        <inertial>
            <origin xyz="0.0095531 0.0016282 -0.0072002" rpy="0 0 0" />
            <mass value="0.1" />
            <inertia ixx="0.1" ixy="0" ixz="0" iyy="0.1" iyz="0" izz="0.1" />
            <!-- <mass value="0.0037844" />
            <inertia ixx="3.6981E-07" ixy="9.8603E-08" ixz="-2.8173E-12" iyy="3.2395E-07" iyz="-2.8028E-12"
            izz="4.6532E-07" /> -->
        </inertial>
        <visual>
            <origin xyz="0 0 0" rpy="0 0 0" />
            <geometry>
                <mesh filename="package://inspire_hand_description/meshes/left/Link13.STL" />
            </geometry>
            <material name="">
                <color rgba="1 1 1 1" />
            </material>
        </visual>
        <collision>
            <origin xyz="0 0 0" rpy="0 0 0" />
            <geometry>
                <mesh filename="package://inspire_hand_description/meshes/left/Link13.STL" />
            </geometry>
        </collision>
    </link>
    <joint name="L_thumb_intermediate_joint" type="revolute">
        <origin xyz="0.04407 -0.034553 -0.0008" rpy="0 0 0" />
        <parent link="L_thumb_proximal" />
        <child link="L_thumb_intermediate" />
        <axis xyz="0 0 -1" />
        <limit lower="0" upper="0.8" effort="1" velocity="0.5" />
        <!-- <mimic joint="L_thumb_proximal_pitch_joint" multiplier="1.6" offset="0" /> -->
    </joint>
    <link name="L_thumb_distal">
        <inertial>
            <origin xyz="0.0092888 -0.004953 -0.0060033" rpy="0 0 0" />
            <mass value="0.1" />
            <inertia ixx="0.1" ixy="0" ixz="0" iyy="0.1" iyz="0" izz="0.1" />
            <!-- <mass value="0.003344" />
            <inertia ixx="1.3632E-07" ixy="5.6787E-08" ixz="-9.1939E-11" iyy="1.4052E-07" iyz="1.2145E-10"
            izz="2.0026E-07" /> -->
        </inertial>
        <visual>
            <origin xyz="0 0 0" rpy="0 0 0" />
            <geometry>
                <mesh filename="package://inspire_hand_description/meshes/left/Link14.STL" />
            </geometry>
            <material name="">
                <color rgba="1 1 1 1" />
            </material>
        </visual>
        <collision>
            <origin xyz="0 0 0" rpy="0 0 0" />
            <geometry>
                <mesh filename="package://inspire_hand_description/meshes/left/Link14.STL" />
            </geometry>
        </collision>
    </link>
    <joint name="L_thumb_distal_joint" type="revolute">
        <origin xyz="0.020248 -0.010156 -0.0012" rpy="0 0 0" />
        <parent link="L_thumb_intermediate" />
        <child link="L_thumb_distal" />
        <axis xyz="0 0 -1" />
        <limit lower="0" upper="1.2" effort="1" velocity="0.5" />
        <!-- <mimic joint="L_thumb_proximal_pitch_joint" multiplier="2.4" offset="0" /> -->
    </joint>
    <link name="L_index_proximal">
        <inertial>
            <origin xyz="0.0012971 -0.011934 -0.0059998" rpy="0 0 0" />
            <mass value="0.1" />
            <inertia ixx="0.1" ixy="0" ixz="0" iyy="0.1" iyz="0" izz="0.1" />
            <!-- <mass value="0.0042405" />
            <inertia ixx="6.6215E-07" ixy="1.8442E-08" ixz="1.3746E-12" iyy="2.1167E-07" iyz="-1.4773E-11"
            izz="6.9402E-07" /> -->
        </inertial>
        <visual>
            <origin xyz="0 0 0" rpy="0 0 0" />
            <geometry>
                <mesh filename="package://inspire_hand_description/meshes/left/Link15.STL" />
            </geometry>
            <material name="">
                <color rgba="0.79216 0.81961 0.93333 1" />
            </material>
        </visual>
        <collision>
            <origin xyz="0 0 0" rpy="0 0 0" />
            <geometry>
                <mesh filename="package://inspire_hand_description/meshes/left/Link15.STL" />
            </geometry>
        </collision>
    </link>
    <joint name="L_index_proximal_joint" type="revolute">
        <origin xyz="0.00028533 -0.13653 0.032268" rpy="-0.034907 0 0" />
        <parent link="L_hand_base_link" />
        <child link="L_index_proximal" />
        <axis xyz="0 0 -1" />
        <limit lower="0" upper="1.7" effort="1" velocity="0.5" />
    </joint>
    <link name="L_index_intermediate">
        <inertial>
            <origin xyz="0.0021753 -0.019567 -0.005" rpy="0 0 0" />
            <mass value="0.1" />
            <inertia ixx="0.1" ixy="0" ixz="0" iyy="0.1" iyz="0" izz="0.1" />
            <!-- <mass value="0.0045682" />
            <inertia ixx="7.6284E-07" ixy="-8.063E-08" ixz="3.6797E-13" iyy="9.4308E-08" iyz="1.5743E-13"
            izz="7.8176E-07" /> -->
        </inertial>
        <visual>
            <origin xyz="0 0 0" rpy="0 0 0" />
            <geometry>
                <mesh filename="package://inspire_hand_description/meshes/left/Link16.STL" />
            </geometry>
            <material name="">
                <color rgba="1 1 1 1" />
            </material>
        </visual>
        <collision>
            <origin xyz="0 0 0" rpy="0 0 0" />
            <geometry>
                <mesh filename="package://inspire_hand_description/meshes/left/Link16.STL" />
            </geometry>
        </collision>
    </link>
    <joint name="L_index_intermediate_joint" type="revolute">
        <origin xyz="-0.0024229 -0.032041 -0.001" rpy="0 0 0" />
        <parent link="L_index_proximal" />
        <child link="L_index_intermediate" />
        <axis xyz="0 0 -1" />
        <limit lower="0" upper="1.7" effort="1" velocity="0.5" />
        <!-- <mimic joint="L_index_proximal_joint" multiplier="1" offset="0" /> -->
    </joint>
    <link name="L_middle_proximal">
        <inertial>
            <origin xyz="0.0012971 -0.011934 -0.0059999" rpy="0 0 0" />
            <mass value="0.1" />
            <inertia ixx="0.1" ixy="0" ixz="0" iyy="0.1" iyz="0" izz="0.1" />
            <!-- <mass value="0.0042405" />
            <inertia ixx="6.6215E-07" ixy="1.8442E-08" ixz="1.2299E-12" iyy="2.1167E-07" iyz="-1.4484E-11"
            izz="6.9402E-07" /> -->
        </inertial>
        <visual>
            <origin xyz="0 0 0" rpy="0 0 0" />
            <geometry>
                <mesh filename="package://inspire_hand_description/meshes/left/Link17.STL" />
            </geometry>
            <material name="">
                <color rgba="0.79216 0.81961 0.93333 1" />
            </material>
        </visual>
        <collision>
            <origin xyz="0 0 0" rpy="0 0 0" />
            <geometry>
                <mesh filename="package://inspire_hand_description/meshes/left/Link17.STL" />
            </geometry>
        </collision>
    </link>
    <joint name="L_middle_proximal_joint" type="revolute">
        <origin xyz="0.00028533 -0.1371 0.01295" rpy="0 0 0" />
        <parent link="L_hand_base_link" />
        <child link="L_middle_proximal" />
        <axis xyz="0 0 -1" />
        <limit lower="0" upper="1.7" effort="1" velocity="0.5" />
    </joint>
    <link name="L_middle_intermediate">
        <inertial>
            <origin xyz="0.001921 -0.020796 -0.0049999" rpy="0 0 0" />
            <mass value="0.1" />
            <inertia ixx="0.1" ixy="0" ixz="0" iyy="0.1" iyz="0" izz="0.1" />
            <!-- <mass value="0.0050397" />
            <inertia ixx="9.5823E-07" ixy="-1.1425E-07" ixz="-2.4186E-12" iyy="1.0646E-07" iyz="3.6974E-12"
            izz="9.8385E-07" /> -->
        </inertial>
        <visual>
            <origin xyz="0 0 0" rpy="0 0 0" />
            <geometry>
                <mesh filename="package://inspire_hand_description/meshes/left/Link18.STL" />
            </geometry>
            <material name="">
                <color rgba="0.82745 0.83922 0.82745 1" />
            </material>
        </visual>
        <collision>
            <origin xyz="0 0 0" rpy="0 0 0" />
            <geometry>
                <mesh filename="package://inspire_hand_description/meshes/left/Link18.STL" />
            </geometry>
        </collision>
    </link>
    <joint name="L_middle_intermediate_joint" type="revolute">
        <origin xyz="-0.0024229 -0.032041 -0.001" rpy="0 0 0" />
        <parent link="L_middle_proximal" />
        <child link="L_middle_intermediate" />
        <axis xyz="0 0 -1" />
        <limit lower="0" upper="1.7" effort="1" velocity="0.5" />
        <!-- <mimic joint="L_middle_proximal_joint" multiplier="1" offset="0" /> -->
    </joint>
    <link name="L_ring_proximal">
        <inertial>
            <origin xyz="0.0012971 -0.011934 -0.0059999" rpy="0 0 0" />
            <mass value="0.1" />
            <inertia ixx="0.1" ixy="0" ixz="0" iyy="0.1" iyz="0" izz="0.1" />
            <!-- <mass value="0.0042405" />
            <inertia ixx="6.6215E-07" ixy="1.8442E-08" ixz="9.6052E-13" iyy="2.1167E-07" iyz="-1.4124E-11"
            izz="6.9402E-07" /> -->
        </inertial>
        <visual>
            <origin xyz="0 0 0" rpy="0 0 0" />
            <geometry>
                <mesh filename="package://inspire_hand_description/meshes/left/Link19.STL" />
            </geometry>
            <material name="">
                <color rgba="0.79216 0.81961 0.93333 1" />
            </material>
        </visual>
        <collision>
            <origin xyz="0 0 0" rpy="0 0 0" />
            <geometry>
                <mesh filename="package://inspire_hand_description/meshes/left/Link19.STL" />
            </geometry>
        </collision>
    </link>
    <joint name="L_ring_proximal_joint" type="revolute">
        <origin xyz="0.00028533 -0.13691 -0.0062872" rpy="0.05236 0 0" />
        <parent link="L_hand_base_link" />
        <child link="L_ring_proximal" />
        <axis xyz="0 0 -1" />
        <limit lower="0" upper="1.7" effort="1" velocity="0.5" />
    </joint>
    <link name="L_ring_intermediate">
        <inertial>
            <origin xyz="0.0021753 -0.019567 -0.005" rpy="0 0 0" />
            <mass value="0.1" />
            <inertia ixx="0.1" ixy="0" ixz="0" iyy="0.1" iyz="0" izz="0.1" />
            <!-- <mass value="0.0045682" />
            <inertia ixx="7.6285E-07" ixy="-8.0631E-08" ixz="3.3472E-14" iyy="9.4308E-08" iyz="-4.4773E-13"
            izz="7.8176E-07" /> -->
        </inertial>
        <visual>
            <origin xyz="0 0 0" rpy="0 0 0" />
            <geometry>
                <mesh filename="package://inspire_hand_description/meshes/left/Link20.STL" />
            </geometry>
            <material name="">
                <color rgba="1 1 1 1" />
            </material>
        </visual>
        <collision>
            <origin xyz="0 0 0" rpy="0 0 0" />
            <geometry>
                <mesh filename="package://inspire_hand_description/meshes/left/Link20.STL" />
            </geometry>
        </collision>
    </link>
    <joint name="L_ring_intermediate_joint" type="revolute">
        <origin xyz="-0.0024229 -0.032041 -0.001" rpy="0 0 0" />
        <parent link="L_ring_proximal" />
        <child link="L_ring_intermediate" />
        <axis xyz="0 0 -1" />
        <limit lower="0" upper="1.7" effort="1" velocity="0.5" />
        <!-- <mimic joint="L_ring_proximal_joint" multiplier="1" offset="0" /> -->
    </joint>
    <link name="L_pinky_proximal">
        <inertial>
            <origin xyz="0.0012971 -0.011934 -0.0059999" rpy="0 0 0" />
            <mass value="0.1" />
            <inertia ixx="0.1" ixy="0" ixz="0" iyy="0.1" iyz="0" izz="0.1" />
            <!-- <mass value="0.0042405" />
            <inertia ixx="6.6215E-07" ixy="1.8442E-08" ixz="1.0279E-12" iyy="2.1167E-07" iyz="-1.4277E-11"
            izz="6.9402E-07" /> -->
        </inertial>
        <visual>
            <origin xyz="0 0 0" rpy="0 0 0" />
            <geometry>
                <mesh filename="package://inspire_hand_description/meshes/left/Link21.STL" />
            </geometry>
            <material name="">
                <color rgba="0.79216 0.81961 0.93333 1" />
            </material>
        </visual>
        <collision>
            <origin xyz="0 0 0" rpy="0 0 0" />
            <geometry>
                <mesh filename="package://inspire_hand_description/meshes/left/Link21.STL" />
            </geometry>
        </collision>
    </link>
    <joint name="L_pinky_proximal_joint" type="revolute">
        <origin xyz="0.00028533 -0.13571 -0.025488" rpy="0.10472 0 0" />
        <parent link="L_hand_base_link" />
        <child link="L_pinky_proximal" />
        <axis xyz="0 0 -1" />
        <limit lower="0" upper="1.7" effort="1" velocity="0.5" />
    </joint>
    <link name="L_pinky_intermediate">
        <inertial>
            <origin xyz="0.0024788 -0.016208 -0.0050001" rpy="0 0 0" />
            <mass value="0.1" />
            <inertia ixx="0.1" ixy="0" ixz="0" iyy="0.1" iyz="0" izz="0.1" />
            <!-- <mass value="0.0036036" />
            <inertia ixx="4.3923E-07" ixy="-4.1355E-08" ixz="1.2263E-12" iyy="7.0315E-08" iyz="3.1311E-12"
            izz="4.4881E-07" /> -->
        </inertial>
        <visual>
            <origin xyz="0 0 0" rpy="0 0 0" />
            <geometry>
                <mesh filename="package://inspire_hand_description/meshes/left/Link22.STL" />
            </geometry>
            <material name="">
                <color rgba="1 1 1 1" />
            </material>
        </visual>
        <collision>
            <origin xyz="0 0 0" rpy="0 0 0" />
            <geometry>
                <mesh filename="package://inspire_hand_description/meshes/left/Link22.STL" />
            </geometry>
        </collision>
    </link>
    <joint name="L_pinky_intermediate_joint" type="revolute">
        <origin xyz="-0.0024229 -0.032041 -0.001" rpy="0 0 0" />
        <parent link="L_pinky_proximal" />
        <child link="L_pinky_intermediate" />
        <axis xyz="0 0 -1" />
        <limit lower="0" upper="1.7" effort="1" velocity="0.5" />
        <!-- <mimic joint="L_pinky_proximal_joint" multiplier="1" offset="0" /> -->
    </joint>
    <!-- Frame coincident with all-zeros TCP on UR controller -->
    <link name="world" />
    <joint name="left_arm_temp_joint" type="fixed">
        <parent link="world" />
        <child link="left_arm_temp" />
        <origin rpy="-0.78539816339 0.0 0.0" xyz="-0.06 0.235 0.415" />
    </joint>
    <link name="left_arm_temp" />
    <joint name="left_world_joint" type="fixed">
        <parent link="left_arm_temp" />
        <child link="left_base_link" />
        <origin rpy="0.0 0.0 -0.785" xyz="-0.001 -0.004 0.0" />
    </joint>
    <!-- measured from model -->
    <!--property
    name="shoulder_height" value="0.089159" /-->
    <!--property
    name="shoulder_offset" value="0.13585" /-->
    <!-- shoulder_offset - elbow_offset + wrist_1_length = 0.10915 -->
    <!--property
    name="upper_arm_length" value="0.42500" /-->
    <!--property
    name="elbow_offset" value="0.1197" /-->
    <!-- CAD measured -->
    <!--property
    name="forearm_length" value="0.39225" /-->
    <!--property
    name="wrist_1_length" value="0.093" /-->
    <!-- CAD measured -->
    <!--property
    name="wrist_2_length" value="0.09465" /-->
    <!-- In CAD this distance is 0.930, but in the spec it is 0.09465 -->
    <!--property
    name="wrist_3_length" value="0.0823" /-->
    <!-- manually measured -->
    <link name="right_base_link">
        <visual>
            <geometry>
                <mesh filename="package://ur_description/meshes/ur5/visual/base.dae" />
            </geometry>
            <material name="LightGrey">
                <color rgba="0.7 0.7 0.7 1.0" />
            </material>
        </visual>
        <collision>
            <geometry>
                <mesh filename="package://ur_description/meshes/ur5/collision/base.stl" />
            </geometry>
        </collision>
        <inertial>
            <mass value="4.0" />
            <origin rpy="0 0 0" xyz="0.0 0.0 0.0" />
            <inertia ixx="0.00443333156" ixy="0.0" ixz="0.0" iyy="0.00443333156" iyz="0.0"
                izz="0.0072" />
        </inertial>
    </link>
    <joint name="right_shoulder_pan_joint" type="revolute">
        <parent link="right_base_link" />
        <child link="right_shoulder_link" />
        <origin rpy="0.0 0.0 0.0" xyz="0.0 0.0 0.089159" />
        <axis xyz="0 0 1" />
        <limit effort="150.0" lower="-6.28318530718" upper="6.28318530718" velocity="3.15" />
        <dynamics damping="0.0" friction="0.0" />
    </joint>
    <link name="right_shoulder_link">
        <visual>
            <geometry>
                <mesh filename="package://ur_description/meshes/ur5/visual/shoulder.dae" />
            </geometry>
            <material name="LightGrey">
                <color rgba="0.7 0.7 0.7 1.0" />
            </material>
        </visual>
        <collision>
            <geometry>
                <mesh filename="package://ur_description/meshes/ur5/collision/shoulder.stl" />
            </geometry>
        </collision>
        <inertial>
            <mass value="3.7" />
            <!-- <origin rpy="0 0 0" xyz="0.0 0.0 0.0" /> -->
            <origin rpy="0.0 0.0 0.0" xyz="0.0 0.00193 -0.02561" />
            <inertia ixx="0.010267495893" ixy="0.0" ixz="0.0" iyy="0.010267495893" iyz="0.0"
                izz="0.00666" />
        </inertial>
    </link>
    <joint name="right_shoulder_lift_joint" type="revolute">
        <parent link="right_shoulder_link" />
        <child link="right_upper_arm_link" />
        <!-- <origin rpy="0.0  -0.78539816339 0.0" xyz="0.0 0.13585 0.0" /> -->
        <origin rpy="0.0 1.570796325 0.0" xyz="0.0 0.13585 0.0" />
        <axis xyz="0 1 0" />
        <limit effort="150.0" lower="-6.2831853" upper="6.2831853" velocity="3.15" />
        <dynamics damping="0.0" friction="0.0" />
    </joint>
    <link name="right_upper_arm_link">
        <visual>
            <geometry>
                <mesh filename="package://ur_description/meshes/ur5/visual/upperarm.dae" />
            </geometry>
            <material name="LightGrey">
                <color rgba="0.7 0.7 0.7 1.0" />
            </material>
        </visual>
        <collision>
            <geometry>
                <mesh filename="package://ur_description/meshes/ur5/collision/upperarm.stl" />
            </geometry>
        </collision>
        <inertial>
            <mass value="8.393" />
            <!-- <origin rpy="0 0 0" xyz="0.0 0.0 0.28" /> -->
            <origin rpy="0.0 0.0 0.0" xyz="0.0 -0.024201 0.2125" />
            <inertia ixx="0.22689067591" ixy="0.0" ixz="0.0" iyy="0.22689067591" iyz="0.0"
                izz="0.0151074" />
        </inertial>
    </link>
    <joint name="right_elbow_joint" type="revolute">
        <parent link="right_upper_arm_link" />
        <child link="right_forearm_link" />
        <!-- <origin rpy="0.0 -1.57079632679 0.0" xyz="0.0 -0.1197 0.425" /> -->
        <origin rpy="0.0 0.0 0.0" xyz="0.0 -0.1197 0.425" />
        <axis xyz="0 1 0" />
        <limit effort="150.0" lower="-6.2831853" upper="6.2831853" velocity="3.15" />
        <dynamics damping="0.0" friction="0.0" />
    </joint>
    <link name="right_forearm_link">
        <visual>
            <geometry>
                <mesh filename="package://ur_description/meshes/ur5/visual/forearm.dae" />
            </geometry>
            <material name="LightGrey">
                <color rgba="0.7 0.7 0.7 1.0" />
            </material>
        </visual>
        <collision>
            <geometry>
                <mesh filename="package://ur_description/meshes/ur5/collision/forearm.stl" />
            </geometry>
        </collision>
        <inertial>
            <mass value="2.275" />
            <!-- <origin rpy="0 0 0" xyz="0.0 0.0 0.25" /> -->
            <origin rpy="0.0 0.0 0.0" xyz="0.0 0.0265 0.11993" />
            <inertia ixx="0.049443313556" ixy="0.0" ixz="0.0" iyy="0.049443313556" iyz="0.0"
                izz="0.004095" />
        </inertial>
    </link>
    <joint name="right_wrist_1_joint" type="revolute">
        <parent link="right_forearm_link" />
        <child link="right_wrist_1_link" />
        <origin rpy="0.0 1.57079632679 0.0" xyz="0.0 0.0 0.39225" />
        <axis xyz="0 1 0" />
        <limit effort="28.0" lower="-6.2831853" upper="6.2831853" velocity="3.2" />
        <dynamics damping="0.0" friction="0.0" />
    </joint>
    <link name="right_wrist_1_link">
        <visual>
            <geometry>
                <mesh filename="package://ur_description/meshes/ur5/visual/wrist1.dae" />
            </geometry>
            <material name="LightGrey">
                <color rgba="0.7 0.7 0.7 1.0" />
            </material>
        </visual>
        <collision>
            <geometry>
                <mesh filename="package://ur_description/meshes/ur5/collision/wrist1.stl" />
            </geometry>
        </collision>
        <inertial>
            <mass value="1.219" />
            <!-- <origin rpy="0 0 0" xyz="0.0 0.0 0.0" /> -->
            <origin rpy="0.0 0.0 0.0" xyz="0.0 0.110949 0.01634" />
            <inertia ixx="0.111172755531" ixy="0.0" ixz="0.0" iyy="0.111172755531" iyz="0.0"
                izz="0.21942" />
        </inertial>
    </link>
    <joint name="right_wrist_2_joint" type="revolute">
        <parent link="right_wrist_1_link" />
        <child link="right_wrist_2_link" />
        <!-- <origin rpy="0.0 0.0 -1.57079632679" xyz="0.0 0.093 0.0" /> -->
        <origin rpy="0.0 0.0 0.0" xyz="0.0 0.093 0.0" />
        <axis xyz="0 0 1" />
        <limit effort="28.0" lower="-6.2831853" upper="6.2831853" velocity="3.2" />
        <dynamics damping="0.0" friction="0.0" />
    </joint>
    <link name="right_wrist_2_link">
        <visual>
            <geometry>
                <mesh filename="package://ur_description/meshes/ur5/visual/wrist2.dae" />
            </geometry>
            <material name="LightGrey">
                <color rgba="0.7 0.7 0.7 1.0" />
            </material>
        </visual>
        <collision>
            <geometry>
                <mesh filename="package://ur_description/meshes/ur5/collision/wrist2.stl" />
            </geometry>
        </collision>
        <inertial>
            <mass value="1.219" />
            <!-- <origin rpy="0 0 0" xyz="0.0 0.0 0.0" /> -->
            <origin rpy="0.0 0.0 0.0" xyz="0.0 0.0018 0.11099" />
            <inertia ixx="0.111172755531" ixy="0.0" ixz="0.0" iyy="0.111172755531" iyz="0.0"
                izz="0.21942" />
        </inertial>
    </link>
    <joint name="right_wrist_3_joint" type="revolute">
        <parent link="right_wrist_2_link" />
        <child link="right_wrist_3_link" />
        <origin rpy="0.0 0.0 0.0" xyz="0.0 0.0 0.09465" />
        <axis xyz="0 1 0" />
        <limit effort="28.0" lower="-6.28318535" upper="6.2831853" velocity="3.2" />
        <dynamics damping="0.0" friction="0.0" />
    </joint>
    <link name="right_wrist_3_link">
        <visual>
            <geometry>
                <mesh filename="package://ur_description/meshes/ur5/visual/wrist3.dae" />
            </geometry>
            <material name="LightGrey">
                <color rgba="0.7 0.7 0.7 1.0" />
            </material>
        </visual>
        <collision>
            <geometry>
                <mesh filename="package://ur_description/meshes/ur5/collision/wrist3.stl" />
            </geometry>
        </collision>
        <inertial>
            <mass value="0.1879" />
            <!-- <origin rpy="0 0 0" xyz="0.0 0.0 0.0" /> -->
            <origin rpy="0.0 0.0 0.0" xyz="0.0 0.001159 0.0" />
            <inertia ixx="0.0171364731454" ixy="0.0" ixz="0.0" iyy="0.0171364731454" iyz="0.0"
                izz="0.033822" />
        </inertial>
    </link>
    <joint name="right_ee_fixed_joint" type="fixed">
        <parent link="right_wrist_3_link" />
        <child link="right_ee_link" />
        <origin rpy="0.0 0.0 1.57079632679" xyz="0.0 0.0823 0.0" />
    </joint>
    <link name="right_ee_link">
        <collision>
            <geometry>
                <box size="0.01 0.01 0.01" />
            </geometry>
            <origin rpy="0 0 0" xyz="-0.01 0 0" />
        </collision>
        <inertial>
            <mass value="0.1" />
            <origin xyz="0 0 0" rpy="0 0 0" />
            <inertia ixx="0.03" iyy="0.03" izz="0.03" ixy="0.0" ixz="0.0" iyz="0.0" />
        </inertial>
    </link>
    <joint name="R_hand_base_joint" type="fixed">
        <origin xyz="-0.017 0.0 0.0" rpy="0 -0.785 1.5714" />
        <parent link="right_ee_link" />
        <child link="R_hand_base_link" />
    </joint>
    <joint name="bottle_top_joint" type="fixed">
        <origin xyz="-0.06 -0.12 -0.1" rpy="0 0 0" />
        <parent link="R_hand_base_link" />
        <child link="bottle_top" />
    </joint>
    <link name="bottle_top" />
    <!-- <link name="R_flange">
      <visual>
        <origin xyz="0 0 0" rpy="0 0 0"/>
        <geometry>
          <mesh filename="package://inspire_hand_description/meshes/right/flange.STL" scale="0.001 0.001
    0.001"/>
        </geometry>
        <material
          name="">
          <color
            rgba="1 1 1 1" />
        </material>
      </visual>
      <collision>
        <origin xyz="0 0 0" rpy="0 0 0"/>
        <geometry>
          <mesh filename="package://inspire_hand_description/meshes/right/flange.STL" scale="0.001 0.001
    0.001"/>
        </geometry>
      </collision>
      <inertial>
        <origin
          xyz="0 0 0"
          rpy="0 0 0" />
        <mass
          value="1.0372398E-01" />
        <inertia
          ixx="8.6985265E-05"
          ixy="0"
          ixz="2.7728445E-07"
          iyy="8.7567207E-05"
          iyz="6.8674339E-07"
          izz="7.4487068E-05"/>
      </inertial>
    </link> -->
    <!-- <joint
      name="R_base_link_joint"
      type="fixed">
      <origin
      xyz="0 0 0"
      rpy="1.570796 0 0" />
      <parent link="R_flange"/>
      <child link="R_hand_base_link"/>
    </joint> -->
    <link name="R_hand_base_link">
        <inertial>
            <origin xyz="-0.0025264 -0.066047 0.0019598" rpy="0 0 0" />
            <mass value="0.14143" />
            <inertia ixx="0.00012281" ixy="2.1711E-06" ixz="1.7709E-06" iyy="8.3832E-05"
                iyz="-1.6551E-06" izz="7.6663E-05" />
        </inertial>
        <visual>
            <origin xyz="0 0 0" rpy="0 0 0" />
            <geometry>
                <mesh filename="package://inspire_hand_description/meshes/right/base_link.STL" />
            </geometry>
            <material name="">
                <color rgba="1 1 1 1" />
            </material>
        </visual>
        <collision>
            <origin xyz="0 0 0" rpy="0 0 0" />
            <geometry>
                <mesh filename="package://inspire_hand_description/meshes/right/base_link.STL" />
            </geometry>
        </collision>
    </link>
    <link name="R_thumb_proximal_base">
        <inertial>
            <origin xyz="-0.0048064 0.0009382 -0.00757" rpy="0 0 0" />
            <mass value="0.1" />
            <inertia ixx="0.1" ixy="0" ixz="0" iyy="0.1" iyz="0" izz="0.1" />
            <!-- <mass value="0.0018869" />
            <inertia ixx="5.816E-08" ixy="1.4539E-08" ixz="4.491E-09" iyy="7.9161E-08" iyz="-1.8727E-09"
            izz="6.7433E-08" /> -->
        </inertial>
        <visual>
            <origin xyz="0 0 0" rpy="0 0 0" />
            <geometry>
                <mesh filename="package://inspire_hand_description/meshes/right/Link11.STL" />
            </geometry>
            <material name="">
                <color rgba="1 1 1 1" />
            </material>
        </visual>
        <collision>
            <origin xyz="0 0 0" rpy="0 0 0" />
            <geometry>
                <mesh filename="package://inspire_hand_description/meshes/right/Link11.STL" />
            </geometry>
        </collision>
    </link>
    <joint name="R_thumb_proximal_yaw_joint" type="revolute">
        <origin xyz="-0.01696 -0.0691 -0.02045" rpy="1.5708 -1.5708 0" />
        <parent link="R_hand_base_link" />
        <child link="R_thumb_proximal_base" />
        <axis xyz="0 0 -1" />
        <limit lower="-0.1" upper="1.3" effort="1" velocity="0.5" />
    </joint>
    <link name="R_thumb_proximal">
        <inertial>
            <origin xyz="0.021932 0.012785 -0.0080386" rpy="0 0 0" />
            <mass value="0.1" />
            <inertia ixx="0.1" ixy="0" ixz="0" iyy="0.1" iyz="0" izz="0.1" />
            <!-- <mass value="0.0066075" />
            <inertia ixx="1.5686E-06" ixy="-7.8296E-07" ixz="8.9143E-10" iyy="1.7353E-06" iyz="-1.0191E-09"
            izz="2.786E-06" /> -->
        </inertial>
        <visual>
            <origin xyz="0 0 0" rpy="0 0 0" />
            <geometry>
                <mesh filename="package://inspire_hand_description/meshes/right/Link12.STL" />
            </geometry>
            <material name="">
                <color rgba="1 1 1 1" />
            </material>
        </visual>
        <collision>
            <origin xyz="0 0 0" rpy="0 0 0" />
            <geometry>
                <mesh filename="package://inspire_hand_description/meshes/right/Link12.STL" />
            </geometry>
        </collision>
    </link>
    <joint name="R_thumb_proximal_pitch_joint" type="revolute">
        <origin xyz="-0.0088099 0.010892 -0.00925" rpy="1.5708 0 2.8587" />
        <parent link="R_thumb_proximal_base" />
        <child link="R_thumb_proximal" />
        <axis xyz="0 0 1" />
        <limit lower="-0.1" upper="0.6" effort="1" velocity="0.5" />
    </joint>
    <link name="R_thumb_intermediate">
        <inertial>
            <origin xyz="0.0095544 -0.0016282 -0.0071997" rpy="0 0 0" />
            <mass value="0.1" />
            <inertia ixx="0.1" ixy="0" ixz="0" iyy="0.1" iyz="0" izz="0.1" />
            <!-- <mass value="0.0037847" />
            <inertia ixx="3.6981E-07" ixy="-9.8581E-08" ixz="-4.7469E-12" iyy="3.2394E-07" iyz="1.0939E-12"
            izz="4.6531E-07" /> -->
        </inertial>
        <visual>
            <origin xyz="0 0 0" rpy="0 0 0" />
            <geometry>
                <mesh filename="package://inspire_hand_description/meshes/right/Link13.STL" />
            </geometry>
            <material name="">
                <color rgba="1 1 1 1" />
            </material>
        </visual>
        <collision>
            <origin xyz="0 0 0" rpy="0 0 0" />
            <geometry>
                <mesh filename="package://inspire_hand_description/meshes/right/Link13.STL" />
            </geometry>
        </collision>
    </link>
    <joint name="R_thumb_intermediate_joint" type="revolute">
        <origin xyz="0.04407 0.034553 -0.0008" rpy="0 0 0" />
        <parent link="R_thumb_proximal" />
        <child link="R_thumb_intermediate" />
        <axis xyz="0 0 1" />
        <limit lower="0" upper="0.8" effort="1" velocity="0.5" />
        <!-- <mimic joint="R_thumb_proximal_pitch_joint" multiplier="1.6" offset="0" /> -->
    </joint>
    <link name="R_thumb_distal">
        <inertial>
            <origin xyz="0.0092888 0.0049529 -0.0060033" rpy="0 0 0" />
            <mass value="0.1" />
            <inertia ixx="0.1" ixy="0" ixz="0" iyy="0.1" iyz="0" izz="0.1" />
            <!-- <mass value="0.0033441" />
            <inertia ixx="1.3632E-07" ixy="-5.6788E-08" ixz="-9.2764E-11" iyy="1.4052E-07" iyz="-1.2283E-10"
            izz="2.0026E-07" /> -->
        </inertial>
        <visual>
            <origin xyz="0 0 0" rpy="0 0 0" />
            <geometry>
                <mesh filename="package://inspire_hand_description/meshes/right/Link14.STL" />
            </geometry>
            <material name="">
                <color rgba="1 1 1 1" />
            </material>
        </visual>
        <collision>
            <origin xyz="0 0 0" rpy="0 0 0" />
            <geometry>
                <mesh filename="package://inspire_hand_description/meshes/right/Link14.STL" />
            </geometry>
        </collision>
    </link>
    <joint name="R_thumb_distal_joint" type="revolute">
        <origin xyz="0.020248 0.010156 -0.0012" rpy="0 0 0" />
        <parent link="R_thumb_intermediate" />
        <child link="R_thumb_distal" />
        <axis xyz="0 0 1" />
        <limit lower="0" upper="1.2" effort="1" velocity="0.5" />
        <!-- <mimic joint="R_thumb_proximal_pitch_joint" multiplier="2.4" offset="0" /> -->
    </joint>
    <link name="R_index_proximal">
        <inertial>
            <origin xyz="0.0012259 0.011942 -0.0060001" rpy="0 0 0" />
            <mass value="0.1" />
            <inertia ixx="0.1" ixy="0" ixz="0" iyy="0.1" iyz="0" izz="0.1" />
            <!-- <mass value="0.0042403" />
            <inertia ixx="6.6232E-07" ixy="-1.5775E-08" ixz="1.8515E-12" iyy="2.1146E-07" iyz="-5.0828E-12"
            izz="6.9398E-07" /> -->
        </inertial>
        <visual>
            <origin xyz="0 0 0" rpy="0 0 0" />
            <geometry>
                <mesh filename="package://inspire_hand_description/meshes/right/Link15.STL" />
            </geometry>
            <material name="">
                <color rgba="1 1 1 1" />
            </material>
        </visual>
        <collision>
            <origin xyz="0 0 0" rpy="0 0 0" />
            <geometry>
                <mesh filename="package://inspire_hand_description/meshes/right/Link15.STL" />
            </geometry>
        </collision>
    </link>
    <joint name="R_index_proximal_joint" type="revolute">
        <origin xyz="0.00028533 -0.13653 -0.032268" rpy="-3.1067 0 0" />
        <parent link="R_hand_base_link" />
        <child link="R_index_proximal" />
        <axis xyz="0 0 1" />
        <limit lower="0" upper="1.7" effort="1" velocity="0.5" />
    </joint>
    <link name="R_index_intermediate">
        <inertial>
            <mass value="0.1" />
            <inertia ixx="0.1" ixy="0" ixz="0" iyy="0.1" iyz="0" izz="0.1" />
            <!-- <origin xyz="0.0019697 0.019589 -0.005" rpy="0 0 0" />
            <mass value="0.0045683" /> -->
            <inertia ixx="7.6111E-07" ixy="8.7637E-08" ixz="-3.7751E-13" iyy="9.6076E-08"
                iyz="9.9444E-13" izz="7.8179E-07" />
        </inertial>
        <visual>
            <origin xyz="0 0 0" rpy="0 0 0" />
            <geometry>
                <mesh filename="package://inspire_hand_description/meshes/right/Link16.STL" />
            </geometry>
            <material name="">
                <color rgba="1 1 1 1" />
            </material>
        </visual>
        <collision>
            <origin xyz="0 0 0" rpy="0 0 0" />
            <geometry>
                <mesh filename="package://inspire_hand_description/meshes/right/Link16.STL" />
            </geometry>
        </collision>
    </link>
    <joint name="R_index_intermediate_joint" type="revolute">
        <origin xyz="-0.0026138 0.032026 -0.001" rpy="0 0 0" />
        <parent link="R_index_proximal" />
        <child link="R_index_intermediate" />
        <axis xyz="0 0 1" />
        <limit lower="0" upper="1.7" effort="1" velocity="0.5" />
        <!-- <mimic joint="R_index_proximal_joint" multiplier="1" offset="0" /> -->
    </joint>
    <link name="R_middle_proximal">
        <inertial>
            <origin xyz="0.001297 0.011934 -0.0060001" rpy="0 0 0" />
            <mass value="0.1" />
            <inertia ixx="0.1" ixy="0" ixz="0" iyy="0.1" iyz="0" izz="0.1" />
            <!-- <mass value="0.0042403" />
            <inertia ixx="6.6211E-07" ixy="-1.8461E-08" ixz="1.8002E-12" iyy="2.1167E-07" iyz="-6.6808E-12"
            izz="6.9397E-07" /> -->
        </inertial>
        <visual>
            <origin xyz="0 0 0" rpy="0 0 0" />
            <geometry>
                <mesh filename="package://inspire_hand_description/meshes/right/Link17.STL" />
            </geometry>
            <material name="">
                <color rgba="1 1 1 1" />
            </material>
        </visual>
        <collision>
            <origin xyz="0 0 0" rpy="0 0 0" />
            <geometry>
                <mesh filename="package://inspire_hand_description/meshes/right/Link17.STL" />
            </geometry>
        </collision>
    </link>
    <joint name="R_middle_proximal_joint" type="revolute">
        <origin xyz="0.00028533 -0.1371 -0.01295" rpy="-3.1416 0 0" />
        <parent link="R_hand_base_link" />
        <child link="R_middle_proximal" />
        <axis xyz="0 0 1" />
        <limit lower="0" upper="1.7" effort="1" velocity="0.5" />
    </joint>
    <link name="R_middle_intermediate">
        <inertial>
            <origin xyz="0.001921 0.020796 -0.005" rpy="0 0 0" />
            <mass value="0.1" />
            <inertia ixx="0.1" ixy="0" ixz="0" iyy="0.1" iyz="0" izz="0.1" />
            <!-- <mass value="0.0050396" />
            <inertia ixx="9.5822E-07" ixy="1.1425E-07" ixz="-2.4791E-12" iyy="1.0646E-07" iyz="5.9173E-12"
            izz="9.8384E-07" /> -->
        </inertial>
        <visual>
            <origin xyz="0 0 0" rpy="0 0 0" />
            <geometry>
                <mesh filename="package://inspire_hand_description/meshes/right/Link18.STL" />
            </geometry>
            <material name="">
                <color rgba="1 1 1 1" />
            </material>
        </visual>
        <collision>
            <origin xyz="0 0 0" rpy="0 0 0" />
            <geometry>
                <mesh filename="package://inspire_hand_description/meshes/right/Link18.STL" />
            </geometry>
        </collision>
    </link>
    <joint name="R_middle_intermediate_joint" type="revolute">
        <origin xyz="-0.0024229 0.032041 -0.001" rpy="0 0 0" />
        <parent link="R_middle_proximal" />
        <child link="R_middle_intermediate" />
        <axis xyz="0 0 1" />
        <limit lower="0" upper="1.7" effort="1" velocity="0.5" />
        <!-- <mimic joint="R_middle_proximal_joint" multiplier="1" offset="0" /> -->
    </joint>
    <link name="R_ring_proximal">
        <inertial>
            <origin xyz="0.001297 0.011934 -0.0060002" rpy="0 0 0" />
            <mass value="0.1" />
            <inertia ixx="0.1" ixy="0" ixz="0" iyy="0.1" iyz="0" izz="0.1" />
            <!-- <mass value="0.0042403" />
            <inertia ixx="6.6211E-07" ixy="-1.8461E-08" ixz="1.5793E-12" iyy="2.1167E-07" iyz="-6.6868E-12"
            izz="6.9397E-07" /> -->
        </inertial>
        <visual>
            <origin xyz="0 0 0" rpy="0 0 0" />
            <geometry>
                <mesh filename="package://inspire_hand_description/meshes/right/Link19.STL" />
            </geometry>
            <material name="">
                <color rgba="1 1 1 1" />
            </material>
        </visual>
        <collision>
            <origin xyz="0 0 0" rpy="0 0 0" />
            <geometry>
                <mesh filename="package://inspire_hand_description/meshes/right/Link19.STL" />
            </geometry>
        </collision>
    </link>
    <joint name="R_ring_proximal_joint" type="revolute">
        <origin xyz="0.00028533 -0.13691 0.0062872" rpy="3.0892 0 0" />
        <parent link="R_hand_base_link" />
        <child link="R_ring_proximal" />
        <axis xyz="0 0 1" />
        <limit lower="0" upper="1.7" effort="1" velocity="0.5" />
    </joint>
    <link name="R_ring_intermediate">
        <inertial>
            <origin xyz="0.0021753 0.019567 -0.005" rpy="0 0 0" />
            <mass value="0.1" />
            <inertia ixx="0.1" ixy="0" ixz="0" iyy="0.1" iyz="0" izz="0.1" />
            <!-- <mass value="0.0045683" />
            <inertia ixx="7.6286E-07" ixy="8.0635E-08" ixz="-6.1562E-13" iyy="9.431E-08" iyz="5.8619E-13"
            izz="7.8177E-07" /> -->
        </inertial>
        <visual>
            <origin xyz="0 0 0" rpy="0 0 0" />
            <geometry>
                <mesh filename="package://inspire_hand_description/meshes/right/Link20.STL" />
            </geometry>
            <material name="">
                <color rgba="1 1 1 1" />
            </material>
        </visual>
        <collision>
            <origin xyz="0 0 0" rpy="0 0 0" />
            <geometry>
                <mesh filename="package://inspire_hand_description/meshes/right/Link20.STL" />
            </geometry>
        </collision>
    </link>
    <joint name="R_ring_intermediate_joint" type="revolute">
        <origin xyz="-0.0024229 0.032041 -0.001" rpy="0 0 0" />
        <parent link="R_ring_proximal" />
        <child link="R_ring_intermediate" />
        <axis xyz="0 0 1" />
        <limit lower="0" upper="1.7" effort="1" velocity="0.5" />
        <!-- <mimic joint="R_ring_proximal_joint" multiplier="1" offset="0" /> -->
    </joint>
    <link name="R_pinky_proximal">
        <inertial>
            <origin xyz="0.001297 0.011934 -0.0060001" rpy="0 0 0" />
            <mass value="0.1" />
            <inertia ixx="0.1" ixy="0" ixz="0" iyy="0.1" iyz="0" izz="0.1" />
            <!-- <mass value="0.0042403" />
            <inertia ixx="6.6211E-07" ixy="-1.8461E-08" ixz="1.6907E-12" iyy="2.1167E-07" iyz="-6.9334E-12"
            izz="6.9397E-07" /> -->
        </inertial>
        <visual>
            <origin xyz="0 0 0" rpy="0 0 0" />
            <geometry>
                <mesh filename="package://inspire_hand_description/meshes/right/Link21.STL" />
            </geometry>
            <material name="">
                <color rgba="1 1 1 1" />
            </material>
        </visual>
        <collision>
            <origin xyz="0 0 0" rpy="0 0 0" />
            <geometry>
                <mesh filename="package://inspire_hand_description/meshes/right/Link21.STL" />
            </geometry>
        </collision>
    </link>
    <joint name="R_pinky_proximal_joint" type="revolute">
        <origin xyz="0.00028533 -0.13571 0.025488" rpy="3.0369 0 0" />
        <parent link="R_hand_base_link" />
        <child link="R_pinky_proximal" />
        <axis xyz="0 0 1" />
        <limit lower="0" upper="1.7" effort="1" velocity="0.5" />
    </joint>
    <link name="R_pinky_intermediate">
        <inertial>
            <origin xyz="0.0024748 0.016203 -0.0050031" rpy="0 0 0" />
            <mass value="0.1" />
            <inertia ixx="0.1" ixy="0" ixz="0" iyy="0.1" iyz="0" izz="0.1" />
            <!-- <mass value="0.0035996" />
            <inertia ixx="4.3913E-07" ixy="4.1418E-08" ixz="3.7168E-11" iyy="7.0247E-08" iyz="5.8613E-11"
            izz="4.4867E-07" /> -->
        </inertial>
        <visual>
            <origin xyz="0 0 0" rpy="0 0 0" />
            <geometry>
                <mesh filename="package://inspire_hand_description/meshes/right/Link22.STL" />
            </geometry>
            <material name="">
                <color rgba="1 1 1 1" />
            </material>
        </visual>
        <collision>
            <origin xyz="0 0 0" rpy="0 0 0" />
            <geometry>
                <mesh filename="package://inspire_hand_description/meshes/right/Link22.STL" />
            </geometry>
        </collision>
    </link>
    <joint name="R_pinky_intermediate_joint" type="revolute">
        <origin xyz="-0.0024229 0.032041 -0.001" rpy="0 0 0" />
        <parent link="R_pinky_proximal" />
        <child link="R_pinky_intermediate" />
        <axis xyz="0 0 1" />
        <limit lower="0" upper="1.7" effort="1" velocity="0.5" />
        <!-- <mimic joint="R_pinky_proximal_joint" multiplier="1" offset="0" /> -->
    </joint>
    <!-- Frame coincident with all-zeros TCP on UR controller -->
    <joint name="right_arm_temp_joint" type="fixed">
        <parent link="world" />
        <child link="right_arm_temp" />
        <origin rpy="  0.78539816339 0.0 0.0" xyz="-0.06 -0.235 0.415" />
    </joint>
    <link name="right_arm_temp" />
    <joint name="right_world_joint" type="fixed">
        <parent link="right_arm_temp" />
        <child link="right_base_link" />
        <origin rpy="0.0 0.0 -2.355" xyz="-0.001 0.004 0" />
    </joint>
    <!-- body part-->
    <link name="base_link">
        <inertial>
            <origin xyz="-0.000962390959686438 0.0854841651293876 -0.0961620681936492" rpy="0 0 0" />
            <mass value="37.1209809492073" />
            <inertia ixx="0.43598678033765" ixy="-0.000423569728196321" ixz="0.00215126921879573"
                iyy="0.232442849103403" iyz="-0.0364214807289123" izz="0.517338123880074" />
        </inertial>
        <visual>
            <origin xyz="0 0 0" rpy="0 0 0" />
            <geometry>
                <mesh filename="package://ur_description/meshes/ur5/base_link.STL" />
            </geometry>
            <material name="">
                <color rgba="0.792156862745098 0.819607843137255 0.933333333333333 1" />
            </material>
        </visual>
        <collision>
            <origin xyz="0 0 0" rpy="0 0 0" />
            <geometry>
                <mesh filename="package://ur_description/meshes/ur5/base_link.STL" />
            </geometry>
        </collision>
    </link>
    <joint name="joint" type="fixed">
        <parent link="world" />
        <child link="base_link" />
        <origin rpy="0 0.0 1.57079632679" xyz="0.0 0.0 0.12" />
    </joint>
    <!--above
    is the part of robot's body -->
    <transmission name="trans_left_shoulder_pan_joint">
        <type>transmission_interface/SimpleTransmission</type>
        <joint name="left_shoulder_pan_joint">
            <hardwareInterface>hardware_interface/EffortJointInterface</hardwareInterface>
        </joint>
        <actuator name="left_shoulder_pan_joint_motor">
            <hardwareInterface>hardware_interface/EffortJointInterface</hardwareInterface>
            <mechanicalReduction>1</mechanicalReduction>
        </actuator>
    </transmission>
    <transmission name="trans_left_shoulder_lift_joint">
        <type>transmission_interface/SimpleTransmission</type>
        <joint name="left_shoulder_lift_joint">
            <hardwareInterface>hardware_interface/EffortJointInterface</hardwareInterface>
        </joint>
        <actuator name="left_shoulder_lift_joint_motor">
            <hardwareInterface>hardware_interface/EffortJointInterface</hardwareInterface>
            <mechanicalReduction>1</mechanicalReduction>
        </actuator>
    </transmission>
    <transmission name="trans_left_elbow_joint">
        <type>transmission_interface/SimpleTransmission</type>
        <joint name="left_elbow_joint">
            <hardwareInterface>hardware_interface/EffortJointInterface</hardwareInterface>
        </joint>
        <actuator name="left_elbow_joint_motor">
            <hardwareInterface>hardware_interface/EffortJointInterface</hardwareInterface>
            <mechanicalReduction>1</mechanicalReduction>
        </actuator>
    </transmission>
    <transmission name="trans_left_wrist_1_joint">
        <type>transmission_interface/SimpleTransmission</type>
        <joint name="left_wrist_1_joint">
            <hardwareInterface>hardware_interface/EffortJointInterface</hardwareInterface>
        </joint>
        <actuator name="left_wrist_1_joint_motor">
            <hardwareInterface>hardware_interface/EffortJointInterface</hardwareInterface>
            <mechanicalReduction>1</mechanicalReduction>
        </actuator>
    </transmission>
    <transmission name="trans_left_wrist_2_joint">
        <type>transmission_interface/SimpleTransmission</type>
        <joint name="left_wrist_2_joint">
            <hardwareInterface>hardware_interface/EffortJointInterface</hardwareInterface>
        </joint>
        <actuator name="left_wrist_2_joint_motor">
            <hardwareInterface>hardware_interface/EffortJointInterface</hardwareInterface>
            <mechanicalReduction>1</mechanicalReduction>
        </actuator>
    </transmission>
    <transmission name="trans_left_wrist_3_joint">
        <type>transmission_interface/SimpleTransmission</type>
        <joint name="left_wrist_3_joint">
            <hardwareInterface>hardware_interface/EffortJointInterface</hardwareInterface>
        </joint>
        <actuator name="left_wrist_3_joint_motor">
            <hardwareInterface>hardware_interface/EffortJointInterface</hardwareInterface>
            <mechanicalReduction>1</mechanicalReduction>
        </actuator>
    </transmission>
    <transmission name="trans_L_thumb_proximal_yaw_joint">
        <type>transmission_interface/SimpleTransmission</type>
        <joint name="L_thumb_proximal_yaw_joint">
            <hardwareInterface>hardware_interface/EffortJointInterface</hardwareInterface>
        </joint>
        <actuator name="L_thumb_proximal_yaw_joint_motor">
            <hardwareInterface>hardware_interface/EffortJointInterface</hardwareInterface>
            <mechanicalReduction>1</mechanicalReduction>
        </actuator>
    </transmission>
    <transmission name="trans_L_thumb_proximal_pitch_joint">
        <type>transmission_interface/SimpleTransmission</type>
        <joint name="L_thumb_proximal_pitch_joint">
            <hardwareInterface>hardware_interface/EffortJointInterface</hardwareInterface>
        </joint>
        <actuator name="L_thumb_proximal_pitch_joint_motor">
            <hardwareInterface>hardware_interface/EffortJointInterface</hardwareInterface>
            <mechanicalReduction>1</mechanicalReduction>
        </actuator>
    </transmission>
    <transmission name="trans_L_thumb_intermediate_joint">
        <type>transmission_interface/SimpleTransmission</type>
        <joint name="L_thumb_intermediate_joint">
            <hardwareInterface>hardware_interface/EffortJointInterface</hardwareInterface>
        </joint>
        <actuator name="L_thumb_intermediate_joint_motor">
            <hardwareInterface>hardware_interface/EffortJointInterface</hardwareInterface>
            <mechanicalReduction>1</mechanicalReduction>
        </actuator>
    </transmission>
    <transmission name="trans_L_thumb_distal_joint">
        <type>transmission_interface/SimpleTransmission</type>
        <joint name="L_thumb_distal_joint">
            <hardwareInterface>hardware_interface/EffortJointInterface</hardwareInterface>
        </joint>
        <actuator name="L_thumb_distal_joint_motor">
            <hardwareInterface>hardware_interface/EffortJointInterface</hardwareInterface>
            <mechanicalReduction>1</mechanicalReduction>
        </actuator>
    </transmission>
    <transmission name="trans_L_index_proximal_joint">
        <type>transmission_interface/SimpleTransmission</type>
        <joint name="L_index_proximal_joint">
            <hardwareInterface>hardware_interface/EffortJointInterface</hardwareInterface>
        </joint>
        <actuator name="L_index_proximal_joint_motor">
            <hardwareInterface>hardware_interface/EffortJointInterface</hardwareInterface>
            <mechanicalReduction>1</mechanicalReduction>
        </actuator>
    </transmission>
    <transmission name="trans_L_index_intermediate_joint">
        <type>transmission_interface/SimpleTransmission</type>
        <joint name="L_index_intermediate_joint">
            <hardwareInterface>hardware_interface/EffortJointInterface</hardwareInterface>
        </joint>
        <actuator name="L_index_intermediate_joint_motor">
            <hardwareInterface>hardware_interface/EffortJointInterface</hardwareInterface>
            <mechanicalReduction>1</mechanicalReduction>
        </actuator>
    </transmission>
    <transmission name="trans_L_middle_proximal_joint">
        <type>transmission_interface/SimpleTransmission</type>
        <joint name="L_middle_proximal_joint">
            <hardwareInterface>hardware_interface/EffortJointInterface</hardwareInterface>
        </joint>
        <actuator name="L_middle_proximal_joint_motor">
            <hardwareInterface>hardware_interface/EffortJointInterface</hardwareInterface>
            <mechanicalReduction>1</mechanicalReduction>
        </actuator>
    </transmission>
    <transmission name="trans_L_middle_intermediate_joint">
        <type>transmission_interface/SimpleTransmission</type>
        <joint name="L_middle_intermediate_joint">
            <hardwareInterface>hardware_interface/EffortJointInterface</hardwareInterface>
        </joint>
        <actuator name="L_middle_intermediate_joint_motor">
            <hardwareInterface>hardware_interface/EffortJointInterface</hardwareInterface>
            <mechanicalReduction>1</mechanicalReduction>
        </actuator>
    </transmission>
    <transmission name="trans_L_ring_proximal_joint">
        <type>transmission_interface/SimpleTransmission</type>
        <joint name="L_ring_proximal_joint">
            <hardwareInterface>hardware_interface/EffortJointInterface</hardwareInterface>
        </joint>
        <actuator name="L_ring_proximal_joint_motor">
            <hardwareInterface>hardware_interface/EffortJointInterface</hardwareInterface>
            <mechanicalReduction>1</mechanicalReduction>
        </actuator>
    </transmission>
    <transmission name="trans_L_ring_intermediate_joint">
        <type>transmission_interface/SimpleTransmission</type>
        <joint name="L_ring_intermediate_joint">
            <hardwareInterface>hardware_interface/EffortJointInterface</hardwareInterface>
        </joint>
        <actuator name="L_ring_intermediate_joint_motor">
            <hardwareInterface>hardware_interface/EffortJointInterface</hardwareInterface>
            <mechanicalReduction>1</mechanicalReduction>
        </actuator>
    </transmission>
    <transmission name="trans_L_pinky_proximal_joint">
        <type>transmission_interface/SimpleTransmission</type>
        <joint name="L_pinky_proximal_joint">
            <hardwareInterface>hardware_interface/EffortJointInterface</hardwareInterface>
        </joint>
        <actuator name="L_pinky_proximal_joint_motor">
            <hardwareInterface>hardware_interface/EffortJointInterface</hardwareInterface>
            <mechanicalReduction>1</mechanicalReduction>
        </actuator>
    </transmission>
    <transmission name="trans_L_pinky_intermediate_joint">
        <type>transmission_interface/SimpleTransmission</type>
        <joint name="L_pinky_intermediate_joint">
            <hardwareInterface>hardware_interface/EffortJointInterface</hardwareInterface>
        </joint>
        <actuator name="L_pinky_intermediate_joint_motor">
            <hardwareInterface>hardware_interface/EffortJointInterface</hardwareInterface>
            <mechanicalReduction>1</mechanicalReduction>
        </actuator>
    </transmission>
    <transmission name="trans_right_shoulder_pan_joint">
        <type>transmission_interface/SimpleTransmission</type>
        <joint name="right_shoulder_pan_joint">
            <hardwareInterface>hardware_interface/EffortJointInterface</hardwareInterface>
        </joint>
        <actuator name="right_shoulder_pan_joint_motor">
            <hardwareInterface>hardware_interface/EffortJointInterface</hardwareInterface>
            <mechanicalReduction>1</mechanicalReduction>
        </actuator>
    </transmission>
    <transmission name="trans_right_shoulder_lift_joint">
        <type>transmission_interface/SimpleTransmission</type>
        <joint name="right_shoulder_lift_joint">
            <hardwareInterface>hardware_interface/EffortJointInterface</hardwareInterface>
        </joint>
        <actuator name="right_shoulder_lift_joint_motor">
            <hardwareInterface>hardware_interface/EffortJointInterface</hardwareInterface>
            <mechanicalReduction>1</mechanicalReduction>
        </actuator>
    </transmission>
    <transmission name="trans_right_elbow_joint">
        <type>transmission_interface/SimpleTransmission</type>
        <joint name="right_elbow_joint">
            <hardwareInterface>hardware_interface/EffortJointInterface</hardwareInterface>
        </joint>
        <actuator name="right_elbow_joint_motor">
            <hardwareInterface>hardware_interface/EffortJointInterface</hardwareInterface>
            <mechanicalReduction>1</mechanicalReduction>
        </actuator>
    </transmission>
    <transmission name="trans_right_wrist_1_joint">
        <type>transmission_interface/SimpleTransmission</type>
        <joint name="right_wrist_1_joint">
            <hardwareInterface>hardware_interface/EffortJointInterface</hardwareInterface>
        </joint>
        <actuator name="right_wrist_1_joint_motor">
            <hardwareInterface>hardware_interface/EffortJointInterface</hardwareInterface>
            <mechanicalReduction>1</mechanicalReduction>
        </actuator>
    </transmission>
    <transmission name="trans_right_wrist_2_joint">
        <type>transmission_interface/SimpleTransmission</type>
        <joint name="right_wrist_2_joint">
            <hardwareInterface>hardware_interface/EffortJointInterface</hardwareInterface>
        </joint>
        <actuator name="right_wrist_2_joint_motor">
            <hardwareInterface>hardware_interface/EffortJointInterface</hardwareInterface>
            <mechanicalReduction>1</mechanicalReduction>
        </actuator>
    </transmission>
    <transmission name="trans_right_wrist_3_joint">
        <type>transmission_interface/SimpleTransmission</type>
        <joint name="right_wrist_3_joint">
            <hardwareInterface>hardware_interface/EffortJointInterface</hardwareInterface>
        </joint>
        <actuator name="right_wrist_3_joint_motor">
            <hardwareInterface>hardware_interface/EffortJointInterface</hardwareInterface>
            <mechanicalReduction>1</mechanicalReduction>
        </actuator>
    </transmission>
    <transmission name="trans_R_thumb_proximal_yaw_joint">
        <type>transmission_interface/SimpleTransmission</type>
        <joint name="R_thumb_proximal_yaw_joint">
            <hardwareInterface>hardware_interface/EffortJointInterface</hardwareInterface>
        </joint>
        <actuator name="R_thumb_proximal_yaw_joint_motor">
            <hardwareInterface>hardware_interface/EffortJointInterface</hardwareInterface>
            <mechanicalReduction>1</mechanicalReduction>
        </actuator>
    </transmission>
    <transmission name="trans_R_thumb_proximal_pitch_joint">
        <type>transmission_interface/SimpleTransmission</type>
        <joint name="R_thumb_proximal_pitch_joint">
            <hardwareInterface>hardware_interface/EffortJointInterface</hardwareInterface>
        </joint>
        <actuator name="R_thumb_proximal_pitch_joint_motor">
            <hardwareInterface>hardware_interface/EffortJointInterface</hardwareInterface>
            <mechanicalReduction>1</mechanicalReduction>
        </actuator>
    </transmission>
    <transmission name="trans_R_thumb_intermediate_joint">
        <type>transmission_interface/SimpleTransmission</type>
        <joint name="R_thumb_intermediate_joint">
            <hardwareInterface>hardware_interface/EffortJointInterface</hardwareInterface>
        </joint>
        <actuator name="R_thumb_intermediate_joint_motor">
            <hardwareInterface>hardware_interface/EffortJointInterface</hardwareInterface>
            <mechanicalReduction>1</mechanicalReduction>
        </actuator>
    </transmission>
    <transmission name="trans_R_thumb_distal_joint">
        <type>transmission_interface/SimpleTransmission</type>
        <joint name="R_thumb_distal_joint">
            <hardwareInterface>hardware_interface/EffortJointInterface</hardwareInterface>
        </joint>
        <actuator name="R_thumb_distal_joint_motor">
            <hardwareInterface>hardware_interface/EffortJointInterface</hardwareInterface>
            <mechanicalReduction>1</mechanicalReduction>
        </actuator>
    </transmission>
    <transmission name="trans_R_index_proximal_joint">
        <type>transmission_interface/SimpleTransmission</type>
        <joint name="R_index_proximal_joint">
            <hardwareInterface>hardware_interface/EffortJointInterface</hardwareInterface>
        </joint>
        <actuator name="R_index_proximal_joint_motor">
            <hardwareInterface>hardware_interface/EffortJointInterface</hardwareInterface>
            <mechanicalReduction>1</mechanicalReduction>
        </actuator>
    </transmission>
    <transmission name="trans_R_index_intermediate_joint">
        <type>transmission_interface/SimpleTransmission</type>
        <joint name="R_index_intermediate_joint">
            <hardwareInterface>hardware_interface/EffortJointInterface</hardwareInterface>
        </joint>
        <actuator name="R_index_intermediate_joint_motor">
            <hardwareInterface>hardware_interface/EffortJointInterface</hardwareInterface>
            <mechanicalReduction>1</mechanicalReduction>
        </actuator>
    </transmission>
    <transmission name="trans_R_middle_proximal_joint">
        <type>transmission_interface/SimpleTransmission</type>
        <joint name="R_middle_proximal_joint">
            <hardwareInterface>hardware_interface/EffortJointInterface</hardwareInterface>
        </joint>
        <actuator name="R_middle_proximal_joint_motor">
            <hardwareInterface>hardware_interface/EffortJointInterface</hardwareInterface>
            <mechanicalReduction>1</mechanicalReduction>
        </actuator>
    </transmission>
    <transmission name="trans_R_middle_intermediate_joint">
        <type>transmission_interface/SimpleTransmission</type>
        <joint name="R_middle_intermediate_joint">
            <hardwareInterface>hardware_interface/EffortJointInterface</hardwareInterface>
        </joint>
        <actuator name="R_middle_intermediate_joint_motor">
            <hardwareInterface>hardware_interface/EffortJointInterface</hardwareInterface>
            <mechanicalReduction>1</mechanicalReduction>
        </actuator>
    </transmission>
    <transmission name="trans_R_ring_proximal_joint">
        <type>transmission_interface/SimpleTransmission</type>
        <joint name="R_ring_proximal_joint">
            <hardwareInterface>hardware_interface/EffortJointInterface</hardwareInterface>
        </joint>
        <actuator name="R_ring_proximal_joint_motor">
            <hardwareInterface>hardware_interface/EffortJointInterface</hardwareInterface>
            <mechanicalReduction>1</mechanicalReduction>
        </actuator>
    </transmission>
    <transmission name="trans_R_ring_intermediate_joint">
        <type>transmission_interface/SimpleTransmission</type>
        <joint name="R_ring_intermediate_joint">
            <hardwareInterface>hardware_interface/EffortJointInterface</hardwareInterface>
        </joint>
        <actuator name="R_ring_intermediate_joint_motor">
            <hardwareInterface>hardware_interface/EffortJointInterface</hardwareInterface>
            <mechanicalReduction>1</mechanicalReduction>
        </actuator>
    </transmission>
    <transmission name="trans_R_pinky_proximal_joint">
        <type>transmission_interface/SimpleTransmission</type>
        <joint name="R_pinky_proximal_joint">
            <hardwareInterface>hardware_interface/EffortJointInterface</hardwareInterface>
        </joint>
        <actuator name="R_pinky_proximal_joint_motor">
            <hardwareInterface>hardware_interface/EffortJointInterface</hardwareInterface>
            <mechanicalReduction>1</mechanicalReduction>
        </actuator>
    </transmission>
    <transmission name="trans_R_pinky_intermediate_joint">
        <type>transmission_interface/SimpleTransmission</type>
        <joint name="R_pinky_intermediate_joint">
            <hardwareInterface>hardware_interface/EffortJointInterface</hardwareInterface>
        </joint>
        <actuator name="R_pinky_intermediate_joint_motor">
            <hardwareInterface>hardware_interface/EffortJointInterface</hardwareInterface>
            <mechanicalReduction>1</mechanicalReduction>
        </actuator>
    </transmission>
    <!-- <gazebo>
        <plugin name="L_thumb_intermediate_joint" filename="libroboticsgroup_gazebo_mimic_joint_plugin.so">
            <joint>L_thumb_intermediate_joint</joint>
            <mimicJoint>L_thumb_proximal_pitch_joint</mimicJoint>
            <multiplier>1.6</multiplier>
        </plugin>
        <plugin name="L_thumb_distal_joint" filename="libroboticsgroup_gazebo_mimic_joint_plugin.so">
            <joint>L_thumb_distal_joint</joint>
            <mimicJoint>L_thumb_proximal_pitch_joint</mimicJoint>
            <multiplier>2.4</multiplier>
        </plugin>
        <plugin name="L_index_intermediate_joint" filename="libroboticsgroup_gazebo_mimic_joint_plugin.so">
            <joint>L_index_intermediate_joint</joint>
            <mimicJoint>L_index_proximal_joint</mimicJoint>
            <multiplier>1</multiplier>
        </plugin>
        <plugin name="L_middle_intermediate_joint"
    filename="libroboticsgroup_gazebo_mimic_joint_plugin.so">
            <joint>L_middle_intermediate_joint</joint>
            <mimicJoint>L_middle_proximal_joint</mimicJoint>
            <multiplier>1</multiplier>
        </plugin>
        <plugin name="L_ring_intermediate_joint" filename="libroboticsgroup_gazebo_mimic_joint_plugin.so">
            <joint>L_ring_intermediate_joint</joint>
            <mimicJoint>L_ring_proximal_joint</mimicJoint>
            <multiplier>1</multiplier>
        </plugin>
        <plugin name="L_pinky_intermediate_joint" filename="libroboticsgroup_gazebo_mimic_joint_plugin.so">
            <joint>L_pinky_intermediate_joint</joint>
            <mimicJoint>L_pinky_proximal_joint</mimicJoint>
            <multiplier>1</multiplier>
        </plugin>
        <plugin name="R_thumb_intermediate_joint" filename="libroboticsgroup_gazebo_mimic_joint_plugin.so">
            <joint>R_thumb_intermediate_joint</joint>
            <mimicJoint>R_thumb_proximal_pitch_joint</mimicJoint>
            <multiplier>1.6</multiplier>
        </plugin>
        <plugin name="R_thumb_distal_joint" filename="libroboticsgroup_gazebo_mimic_joint_plugin.so">
            <joint>R_thumb_distal_joint</joint>
            <mimicJoint>R_thumb_proximal_pitch_joint</mimicJoint>
            <multiplier>2.4</multiplier>
        </plugin>
        <plugin name="R_index_intermediate_joint" filename="libroboticsgroup_gazebo_mimic_joint_plugin.so">
            <joint>R_index_intermediate_joint</joint>
            <mimicJoint>R_index_proximal_joint</mimicJoint>
            <multiplier>1</multiplier>
        </plugin>
        <plugin name="R_middle_intermediate_joint"
    filename="libroboticsgroup_gazebo_mimic_joint_plugin.so">
            <joint>R_middle_intermediate_joint</joint>
            <mimicJoint>R_middle_proximal_joint</mimicJoint>
            <multiplier>1</multiplier>
        </plugin>
        <plugin name="R_ring_intermediate_joint" filename="libroboticsgroup_gazebo_mimic_joint_plugin.so">
            <joint>R_ring_intermediate_joint</joint>
            <mimicJoint>R_ring_proximal_joint</mimicJoint>
            <multiplier>1</multiplier>
        </plugin>
        <plugin name="R_pinky_intermediate_joint" filename="libroboticsgroup_gazebo_mimic_joint_plugin.so">
            <joint>R_pinky_intermediate_joint</joint>
            <mimicJoint>R_pinky_proximal_joint</mimicJoint>
            <multiplier>1</multiplier>
        </plugin>
    </gazebo> -->
</robot>
